Workbook

Sheet Dashboard
A1: FIFA World Cup 2026 — Tournament Dashboard
A3: All figures update automatically from the raw data sheets and PivotTables sheet.
A5: =COUNT(Teams!$A$2:$A$49) -> 48 | C5: =COUNT(Matches!$A$2:$A$105) -> 104 | E5: =SUM(Matches!$P$2:$P$105) -> 308 | G5: =SUM(Matches!$P$2:$P$105)/COUNT(Matches!$A$2:$A$105) -> 2.9615385 | I5: =PivotTables!$Q$16&" ("&PivotTables!$T$16&")" -> Kylian Mbappe (10) | K5: =PivotTables!$B$4&" ("&PivotTables!$L$4&" pts)" -> Spain (22 pts)
A8: Total Teams | C8: Total Matches | E8: Total Goals | G8: Avg Goals / Match | I8: Top Scorer | K8: Points Leader

Sheet PivotTables
A1: Team Performance Summary | O1: Goals by Tournament Stage | V1: Stadium Utilization
A2: Every team ranked by tournament points, then goal difference. Source: MatchTeamStats. | O2: Source: Matches. | V2: Source: Matches, Stadiums.
A3: TeamID | B3: Team | C3: Confederation | D3: Group | E3: MP | F3: W | G3: D | H3: L | I3: GF | J3: GA | K3: GD | L3: Pts | M3: Win % | O3: Stage | P3: Matches | Q3: Total Goals | R3: Avg Goals/Match | V3: StadiumID | W3: Stadium | X3: City | Y3: Matches Hosted | Z3: Total Goals | AA3: Avg Goals/Match
A4: 10 | B4: =IFERROR(INDEX(Teams!$B$2:$B$49,MATCH($A4,Teams!$A$2:$A$49,0)),"") -> Spain | C4: =IFERROR(INDEX(Teams!$D$2:$D$49,MATCH($A4,Teams!$A$2:$A$49,0)),"") -> UEFA | D4: =IFERROR(INDEX(Teams!$E$2:$E$49,MATCH($A4,Teams!$A$2:$A$49,0)),"") -> Group H | E4: =COUNTIF(MatchTeamStats!$F$2:$F$209,$A4) -> 8 | F4: =COUNTIFS(MatchTeamStats!$F$2:$F$209,$A4,MatchTeamStats!$L$2:$L$209,"Win") -> 7 | G4: =COUNTIFS(MatchTeamStats!$F$2:$F$209,$A4,MatchTeamStats!$L$2:$L$209,"Draw") -> 1 | H4: =COUNTIFS(MatchTeamStats!$F$2:$F$209,$A4,MatchTeamStats!$L$2:$L$209,"Loss") -> 0 | I4: =SUMIFS(MatchTeamStats!$J$2:$J$209,MatchTeamStats!$F$2:$F$209,$A4) -> 14 | J4: =SUMIFS(MatchTeamStats!$K$2:$K$209,MatchTeamStats!$F$2:$F$209,$A4) -> 1 | K4: =I4-J4 -> 13 | L4: =SUMIFS(MatchTeamStats!$V$2:$V$209,MatchTeamStats!$F$2:$F$209,$A4) -> 22 | M4: =IFERROR(F4/E4,0) -> 0.875 | O4: First Stage | P4: =COUNTIF(Matches!$C$2:$C$105,$O4) -> 72 | Q4: =SUMIFS(Matches!$P$2:$P$105,Matches!$C$2:$C$105,$O4) -> 215 | R4: =IFERROR(Q4/P4,0) -> 2.9861111 | V4: 6 | W4: =IFERROR(INDEX(Stadiums!$B$2:$B$17,MATCH($V4,Stadiums!$A$2:$A$17,0)),"") -> Atlanta Stadium | X4: =IFERROR(INDEX(Stadiums!$C$2:$C$17,MATCH($V4,Stadiums!$A$2:$A$17,0)),"") -> Atlanta, Georgia | Y4: =COUNTIF(Matches!$E$2:$E$105,$V4) -> 8 | Z4: =SUMIFS(Matches!$P$2:$P$105,Matches!$E$2:$E$105,$V4) -> 27 | AA4: =IFERROR(Z4/Y4,0) -> 3.375
A5: 1 | B5: =IFERROR(INDEX(Teams!$B$2:$B$49,MATCH($A5,Teams!$A$2:$A$49,0)),"") -> Argentina | C5: =IFERROR(INDEX(Teams!$D$2:$D$49,MATCH($A5,Teams!$A$2:$A$49,0)),"") -> CONMEBOL | D5: =IFERROR(INDEX(Teams!$E$2:$E$49,MATCH($A5,Teams!$A$2:$A$49,0)),"") -> Group J | E5: =COUNTIF(MatchTeamStats!$F$2:$F$209,$A5) -> 8 | F5: =COUNTIFS(MatchTeamStats!$F$2:$F$209,$A5,MatchTeamStats!$L$2:$L$209,"Win") -> 7 | G5: =COUNTIFS(MatchTeamStats!$F$2:$F$209,$A5,MatchTeamStats!$L$2:$L$209,"Draw") -> 0 | H5: =COUNTIFS(MatchTeamStats!$F$2:$F$209,$A5,MatchTeamStats!$L$2:$L$209,"Loss") -> 1 | I5: =SUMIFS(MatchTeamStats!$J$2:$J$209,MatchTeamStats!$F$2:$F$209,$A5) -> 19 | J5: =SUMIFS(MatchTeamStats!$K$2:$K$209,MatchTeamStats!$F$2:$F$209,$A5) -> 8 | K5: =I5-J5 -> 11 | L5: =SUMIFS(MatchTeamStats!$V$2:$V$209,MatchTeamStats!$F$2:$F$209,$A5) -> 21 | M5: =IFERROR(F5/E5,0) -> 0.875 | O5: Round of 32 | P5: =COUNTIF(Matches!$C$2:$C$105,$O5) -> 16 | Q5: =SUMIFS(Matches!$P$2:$P$105,Matches!$C$2:$C$105,$O5) -> 42 | R5: =IFERROR(Q5/P5,0) -> 2.625 | V5: 9 | W5: =IFERROR(INDEX(Stadiums!$B$2:$B$17,MATCH($V5,Stadiums!$A$2:$A$17,0)),"") -> Houston Stadium | X5: =IFERROR(INDEX(Stadiums!$C$2:$C$17,MATCH($V5,Stadiums!$A$2:$A$17,0)),"") -> Houston, Texas | Y5: =COUNTIF(Matches!$E$2:$E$105,$V5) -> 7 | Z5: =SUMIFS(Matches!$P$2:$P$105,Matches!$E$2:$E$105,$V5) -> 27 | AA5: =IFERROR(Z5/Y5,0) -> 3.8571429
A6: 5 | B6: =IFERROR(INDEX(Teams!$B$2:$B$49,MATCH($A6,Teams!$A$2:$A$49,0)),"") -> England | C6: =IFERROR(INDEX(Teams!$D$2:$D$49,MATCH($A6,Teams!$A$2:$A$49,0)),"") -> UEFA | D6: =IFERROR(INDEX(Teams!$E$2:$E$49,MATCH($A6,Teams!$A$2:$A$49,0)),"") -> Group L | E6: =COUNTIF(MatchTeamStats!$F$2:$F$209,$A6) -> 8 | F6: =COUNTIFS(MatchTeamStats!$F$2:$F$209,$A6,MatchTeamStats!$L$2:$L$209,"Win") -> 6 | G6: =COUNTIFS(MatchTeamStats!$F$2:$F$209,$A6,MatchTeamStats!$L$2:$L$209,"Draw") -> 1 | H6: =COUNTIFS(MatchTeamStats!$F$2:$F$209,$A6,MatchTeamStats!$L$2:$L$209,"Loss") -> 1 | I6: =SUMIFS(MatchTeamStats!$J$2:$J$209,MatchTeamStats!$F$2:$F$209,$A6) -> 20 | J6: =SUMIFS(MatchTeamStats!$K$2:$K$209,MatchTeamStats!$F$2:$F$209,$A6) -> 12 | K6: =I6-J6 -> 8 | L6: =SUMIFS(MatchTeamStats!$V$2:$V$209,MatchTeamStats!$F$2:$F$209,$A6) -> 19 | M6: =IFERROR(F6/E6,0) -> 0.75 | O6: Round of 16 | P6: =COUNTIF(Matches!$C$2:$C$105,$O6) -> 8 | Q6: =SUMIFS(Matches!$P$2:$P$105,Matches!$C$2:$C$105,$O6) -> 23 | R6: =IFERROR(Q6/P6,0) -> 2.875 | V6: 12 | W6: =IFERROR(INDEX(Stadiums!$B$2:$B$17,MATCH($V6,Stadiums!$A$2:$A$17,0)),"") -> Miami Stadium | X6: =IFERROR(INDEX(Stadiums!$C$2:$C$17,MATCH($V6,Stadiums!$A$2:$A$17,0)),"") -> Miami Gardens, Florida | Y6: =COUNTIF(Matches!$E$2:$E$105,$V6) -> 7 | Z6: =SUMIFS(Matches!$P$2:$P$105,Matches!$E$2:$E$105,$V6) -> 27 | AA6: =IFERROR(Z6/Y6,0) -> 3.8571429
A7: 6 | B7: =IFERROR(INDEX(Teams!$B$2:$B$49,MATCH($A7,Teams!$A$2:$A$49,0)),"") -> France | C7: =IFERROR(INDEX(Teams!$D$2:$D$49,MATCH($A7,Teams!$A$2:$A$49,0)),"") -> UEFA | D7: =IFERROR(INDEX(Teams!$E$2:$E$49,MATCH($A7,Teams!$A$2:$A$49,0)),"") -> Group I | E7: =COUNTIF(MatchTeamStats!$F$2:$F$209,$A7) -> 8 | F7: =COUNTIFS(MatchTeamStats!$F$2:$F$209,$A7,MatchTeamStats!$L$2:$L$209,"Win") -> 6 | G7: =COUNTIFS(MatchTeamStats!$F$2:$F$209,$A7,MatchTeamStats!$L$2:$L$209,"Draw") -> 0 | H7: =COUNTIFS(MatchTeamStats!$F$2:$F$209,$A7,MatchTeamStats!$L$2:$L$209,"Loss") -> 2 | I7: =SUMIFS(MatchTeamStats!$J$2:$J$209,MatchTeamStats!$F$2:$F$209,$A7) -> 20 | J7: =SUMIFS(MatchTeamStats!$K$2:$K$209,MatchTeamStats!$F$2:$F$209,$A7) -> 10 | K7: =I7-J7 -> 10 | L7: =SUMIFS(MatchTeamStats!$V$2:$V$209,MatchTeamStats!$F$2:$F$209,$A7) -> 18 | M7: =IFERROR(F7/E7,0) -> 0.75 | O7: Quarter-final | P7: =COUNTIF(Matches!$C$2:$C$105,$O7) -> 4 | Q7: =SUMIFS(Matches!$P$2:$P$105,Matches!$C$2:$C$105,$O7) -> 12 | R7: =IFERROR(Q7/P7,0) -> 3 | V7: 8 | W7: =IFERROR(INDEX(Stadiums!$B$2:$B$17,MATCH($V7,Stadiums!$A$2:$A$17,0)),"") -> Dallas Stadium | X7: =IFERROR(INDEX(Stadiums!$C$2:$C$17,MATCH($V7,Stadiums!$A$2:$A$17,0)),"") -> Arlington, Texas | Y7: =COUNTIF(Matches!$E$2:$E$105,$V7) -> 9 | Z7: =SUMIFS(Matches!$P$2:$P$105,Matches!$E$2:$E$105,$V7) -> 26 | AA7: =IFERROR(Z7/Y7,0) -> 2.8888889
A8: 8 | B8: =IFERROR(INDEX(Teams!$B$2:$B$49,MATCH($A8,Teams!$A$2:$A$49,0)),"") -> Mexico | C8: =IFERROR(INDEX(Teams!$D$2:$D$49,MATCH($A8,Teams!$A$2:$A$49,0)),"") -> CONCACAF | D8: =IFERROR(INDEX(Teams!$E$2:$E$49,MATCH($A8,Teams!$A$2:$A$49,0)),"") -> Group A | E8: =COUNTIF(MatchTeamStats!$F$2:$F$209,$A8) -> 5 | F8: =COUNTIFS(MatchTeamStats!$F$2:$F$209,$A8,MatchTeamStats!$L$2:$L$209,"Win") -> 4 | G8: =COUNTIFS(MatchTeamStats!$F$2:$F$209,$A8,MatchTeamStats!$L$2:$L$209,"Draw") -> 0 | H8: =COUNTIFS(MatchTeamStats!$F$2:$F$209,$A8,MatchTeamStats!$L$2:$L$209,"Loss") -> 1 | I8: =SUMIFS(MatchTeamStats!$J$2:$J$209,MatchTeamStats!$F$2:$F$209,$A8) -> 10 | J8: =SUMIFS(MatchTeamStats!$K$2:$K$209,MatchTeamStats!$F$2:$F$209,$A8) -> 3 | K8: =I8-J8 -> 7 | L8: =SUMIFS(MatchTeamStats!$V$2:$V$209,MatchTeamStats!$F$2:$F$209,$A8) -> 12 | M8: =IFERROR(F8/E8,0) -> 0.8 | O8: Semi-final | P8: =COUNTIF(Matches!$C$2:$C$105,$O8) -> 2 | Q8: =SUMIFS(Matches!$P$2:$P$105,Matches!$C$2:$C$105,$O8) -> 5 | R8: =IFERROR(Q8/P8,0) -> 2.5 | V8: 11 | W8: =IFERROR(INDEX(Stadiums!$B$2:$B$17,MATCH($V8,Stadiums!$A$2:$A$17,0)),"") -> Los Angeles Stadium | X8: =IFERROR(INDEX(Stadiums!$C$2:$C$17,MATCH($V8,Stadiums!$A$2:$A$17,0)),"") -> Inglewood, California | Y8: =COUNTIF(Matches!$E$2:$E$105,$V8) -> 8 | Z8: =SUMIFS(Matches!$P$2:$P$105,Matches!$E$2:$E$105,$V8) -> 26 | AA8: =IFERROR(Z8/Y8,0) -> 3.25
A9: 22 | B9: =IFERROR(INDEX(Teams!$B$2:$B$49,MATCH($A9,Teams!$A$2:$A$49,0)),"") -> Norway | C9: =IFERROR(INDEX(Teams!$D$2:$D$49,MATCH($A9,Teams!$A$2:$A$49,0)),"") -> UEFA | D9: =IFERROR(INDEX(Teams!$E$2:$E$49,MATCH($A9,Teams!$A$2:$A$49,0)),"") -> Group I | E9: =COUNTIF(MatchTeamStats!$F$2:$F$209,$A9) -> 6 | F9: =COUNTIFS(MatchTeamStats!$F$2:$F$209,$A9,MatchTeamStats!$L$2:$L$209,"Win") -> 4 | G9: =COUNTIFS(MatchTeamStats!$F$2:$F$209,$A9,MatchTeamStats!$L$2:$L$209,"Draw") -> 0 | H9: =COUNTIFS(MatchTeamStats!$F$2:$F$209,$A9,MatchTeamStats!$L$2:$L$209,"Loss") -> 2 | I9: =SUMIFS(MatchTeamStats!$J$2:$J$209,MatchTeamStats!$F$2:$F$209,$A9) -> 13 | J9: =SUMIFS(MatchTeamStats!$K$2:$K$209,MatchTeamStats!$F$2:$F$209,$A9) -> 11 | K9: =I9-J9 -> 2 | L9: =SUMIFS(MatchTeamStats!$V$2:$V$209,MatchTeamStats!$F$2:$F$209,$A9) -> 12 | M9: =IFERROR(F9/E9,0) -> 0.66666667 | O9: Bronze final | P9: =COUNTIF(Matches!$C$2:$C$105,$O9) -> 1 | Q9: =SUMIFS(Matches!$P$2:$P$105,Matches!$C$2:$C$105,$O9) -> 10 | R9: =IFERROR(Q9/P9,0) -> 10 | V9: 13 | W9: =IFERROR(INDEX(Stadiums!$B$2:$B$17,MATCH($V9,Stadiums!$A$2:$A$17,0)),"") -> New York New Jersey Stadium | X9: =IFERROR(INDEX(Stadiums!$C$2:$C$17,MATCH($V9,Stadiums!$A$2:$A$17,0)),"") -> East Rutherford, New Jersey | Y9: =COUNTIF(Matches!$E$2:$E$105,$V9) -> 8 | Z9: =SUMIFS(Matches!$P$2:$P$105,Matches!$E$2:$E$105,$V9) -> 23 | AA9: =IFERROR(Z9/Y9,0) -> 2.875
A10: 2 | B10: =IFERROR(INDEX(Teams!$B$2:$B$49,MATCH($A10,Teams!$A$2:$A$49,0)),"") -> Belgium | C10: =IFERROR(INDEX(Teams!$D$2:$D$49,MATCH($A10,Teams!$A$2:$A$49,0)),"") -> UEFA | D10: =IFERROR(INDEX(Teams!$E$2:$E$49,MATCH($A10,Teams!$A$2:$A$49,0)),"") -> Group G | E10: =COUNTIF(MatchTeamStats!$F$2:$F$209,$A10) -> 6 | F10: =COUNTIFS(MatchTeamStats!$F$2:$F$209,$A10,MatchTeamStats!$L$2:$L$209,"Win") -> 3 | G10: =COUNTIFS(MatchTeamStats!$F$2:$F$209,$A10,MatchTeamStats!$L$2:$L$209,"Draw") -> 2 | H10: =COUNTIFS(MatchTeamStats!$F$2:$F$209,$A10,MatchTeamStats!$L$2:$L$209,"Loss") -> 1 | I10: =SUMIFS(MatchTeamStats!$J$2:$J$209,MatchTeamStats!$F$2:$F$209,$A10) -> 14 | J10: =SUMIFS(MatchTeamStats!$K$2:$K$209,MatchTeamStats!$F$2:$F$209,$A10) -> 7 | K10: =I10-J10 -> 7 | L10: =SUMIFS(MatchTeamStats!$V$2:$V$209,MatchTeamStats!$F$2:$F$209,$A10) -> 11 | M10: =IFERROR(F10/E10,0) -> 0.5 | O10: Final | P10: =COUNTIF(Matches!$C$2:$C$105,$O10) -> 1 | Q10: =SUMIFS(Matches!$P$2:$P$105,Matches!$C$2:$C$105,$O10) -> 1 | R10: =IFERROR(Q10/P10,0) -> 1 | V10: 2 | W10: =IFERROR(INDEX(Stadiums!$B$2:$B$17,MATCH($V10,Stadiums!$A$2:$A$17,0)),"") -> BC Place Vancouver | X10: =IFERROR(INDEX(Stadiums!$C$2:$C$17,MATCH($V10,Stadiums!$A$2:$A$17,0)),"") -> Vancouver, British Colombia | Y10: =COUNTIF(Matches!$E$2:$E$105,$V10) -> 7 | Z10: =SUMIFS(Matches!$P$2:$P$105,Matches!$E$2:$E$105,$V10) -> 23 | AA10: =IFERROR(Z10/Y10,0) -> 3.2857143
A11: 4 | B11: =IFERROR(INDEX(Teams!$B$2:$B$49,MATCH($A11,Teams!$A$2:$A$49,0)),"") -> Colombia | C11: =IFERROR(INDEX(Teams!$D$2:$D$49,MATCH($A11,Teams!$A$2:$A$49,0)),"") -> CONMEBOL | D11: =IFERROR(INDEX(Teams!$E$2:$E$49,MATCH($A11,Teams!$A$2:$A$49,0)),"") -> Group K | E11: =COUNTIF(MatchTeamStats!$F$2:$F$209,$A11) -> 5 | F11: =COUNTIFS(MatchTeamStats!$F$2:$F$209,$A11,MatchTeamStats!$L$2:$L$209,"Win") -> 3 | G11: =COUNTIFS(MatchTeamStats!$F$2:$F$209,$A11,MatchTeamStats!$L$2:$L$209,"Draw") -> 2 | H11: =COUNTIFS(MatchTeamStats!$F$2:$F$209,$A11,MatchTeamStats!$L$2:$L$209,"Loss") -> 0 | I11: =SUMIFS(MatchTeamStats!$J$2:$J$209,MatchTeamStats!$F$2:$F$209,$A11) -> 5 | J11: =SUMIFS(MatchTeamStats!$K$2:$K$209,MatchTeamStats!$F$2:$F$209,$A11) -> 1 | K11: =I11-J11 -> 4 | L11: =SUMIFS(MatchTeamStats!$V$2:$V$209,MatchTeamStats!$F$2:$F$209,$A11) -> 11 | M11: =IFERROR(F11/E11,0) -> 0.6 | V11: 16 | W11: =IFERROR(INDEX(Stadiums!$B$2:$B$17,MATCH($V11,Stadiums!$A$2:$A$17,0)),"") -> Seattle Stadium | X11: =IFERROR(INDEX(Stadiums!$C$2:$C$17,MATCH($V11,Stadiums!$A$2:$A$17,0)),"") -> Seattle, Washington | Y11: =COUNTIF(Matches!$E$2:$E$105,$V11) -> 6 | Z11: =SUMIFS(Matches!$P$2:$P$105,Matches!$E$2:$E$105,$V11) -> 20 | AA11: =IFERROR(Z11/Y11,0) -> 3.3333333
A12: 11 | B12: =IFERROR(INDEX(Teams!$B$2:$B$49,MATCH($A12,Teams!$A$2:$A$49,0)),"") -> Switzerland | C12: =IFERROR(INDEX(Teams!$D$2:$D$49,MATCH($A12,Teams!$A$2:$A$49,0)),"") -> UEFA | D12: =IFERROR(INDEX(Teams!$E$2:$E$49,MATCH($A12,Teams!$A$2:$A$49,0)),"") -> Group B | E12: =COUNTIF(MatchTeamStats!$F$2:$F$209,$A12) -> 6 | F12: =COUNTIFS(MatchTeamStats!$F$2:$F$209,$A12,MatchTeamStats!$L$2:$L$209,"Win") -> 3 | G12: =COUNTIFS(MatchTeamStats!$F$2:$F$209,$A12,MatchTeamStats!$L$2:$L$209,"Draw") -> 2 | H12: =COUNTIFS(MatchTeamStats!$F$2:$F$209,$A12,MatchTeamStats!$L$2:$L$209,"Loss") -> 1 | I12: =SUMIFS(MatchTeamStats!$J$2:$J$209,MatchTeamStats!$F$2:$F$209,$A12) -> 10 | J12: =SUMIFS(MatchTeamStats!$K$2:$K$209,MatchTeamStats!$F$2:$F$209,$A12) -> 6 | K12: =I12-J12 -> 4 | L12: =SUMIFS(MatchTeamStats!$V$2:$V$209,MatchTeamStats!$F$2:$F$209,$A12) -> 11 | M12: =IFERROR(F12/E12,0) -> 0.5 | V12: 10 | W12: =IFERROR(INDEX(Stadiums!$B$2:$B$17,MATCH($V12,Stadiums!$A$2:$A$17,0)),"") -> Kansas City Stadium | X12: =IFERROR(INDEX(Stadiums!$C$2:$C$17,MATCH($V12,Stadiums!$A$2:$A$17,0)),"") -> Kansas City, Missouri | Y12: =COUNTIF(Matches!$E$2:$E$105,$V12) -> 6 | Z12: =SUMIFS(Matches!$P$2:$P$105,Matches!$E$2:$E$105,$V12) -> 18 | AA12: =IFERROR(Z12/Y12,0) -> 3
A13: 21 | B13: =IFERROR(INDEX(Teams!$B$2:$B$49,MATCH($A13,Teams!$A$2:$A$49,0)),"") -> Morocco | C13: =IFERROR(INDEX(Teams!$D$2:$D$49,MATCH($A13,Teams!$A$2:$A$49,0)),"") -> CAF | D13: =IFERROR(INDEX(Teams!$E$2:$E$49,MATCH($A13,Teams!$A$2:$A$49,0)),"") -> Group C | E13: =COUNTIF(MatchTeamStats!$F$2:$F$209,$A13) -> 6 | F13: =COUNTIFS(MatchTeamStats!$F$2:$F$209,$A13,MatchTeamStats!$L$2:$L$209,"Win") -> 3 | G13: =COUNTIFS(MatchTeamStats!$F$2:$F$209,$A13,MatchTeamStats!$L$2:$L$209,"Draw") -> 2 | H13: =COUNTIFS(MatchTeamStats!$F$2:$F$209,$A13,MatchTeamStats!$L$2:$L$209,"Loss") -> 1 | I13: =SUMIFS(MatchTeamStats!$J$2:$J$209,MatchTeamStats!$F$2:$F$209,$A13) -> 10 | J13: =SUMIFS(MatchTeamStats!$K$2:$K$209,MatchTeamStats!$F$2:$F$209,$A13) -> 6 | K13: =I13-J13 -> 4 | L13: =SUMIFS(MatchTeamStats!$V$2:$V$209,MatchTeamStats!$F$2:$F$209,$A13) -> 11 | M13: =IFERROR(F13/E13,0) -> 0.5 | O13: Top 15 Goal Scorers | V13: 3 | W13: =IFERROR(INDEX(Stadiums!$B$2:$B$17,MATCH($V13,Stadiums!$A$2:$A$17,0)),"") -> Mexico City Stadium | X13: =IFERROR(INDEX(Stadiums!$C$2:$C$17,MATCH($V13,Stadiums!$A$2:$A$17,0)),"") -> Mexico City | Y13: =COUNTIF(Matches!$E$2:$E$105,$V13) -> 5 | Z13: =SUMIFS(Matches!$P$2:$P$105,Matches!$E$2:$E$105,$V13) -> 16 | AA13: =IFERROR(Z13/Y13,0) -> 3.2
A14: 3 | B14: =IFERROR(INDEX(Teams!$B$2:$B$49,MATCH($A14,Teams!$A$2:$A$49,0)),"") -> Brazil | C14: =IFERROR(INDEX(Teams!$D$2:$D$49,MATCH($A14,Teams!$A$2:$A$49,0)),"") -> CONMEBOL | D14: =IFERROR(INDEX(Teams!$E$2:$E$49,MATCH($A14,Teams!$A$2:$A$49,0)),"") -> Group C | E14: =COUNTIF(MatchTeamStats!$F$2:$F$209,$A14) -> 5 | F14: =COUNTIFS(MatchTeamStats!$F$2:$F$209,$A14,MatchTeamStats!$L$2:$L$209,"Win") -> 3 | G14: =COUNTIFS(MatchTeamStats!$F$2:$F$209,$A14,MatchTeamStats!$L$2:$L$209,"Draw") -> 1 | H14: =COUNTIFS(MatchTeamStats!$F$2:$F$209,$A14,MatchTeamStats!$L$2:$L$209,"Loss") -> 1 | I14: =SUMIFS(MatchTeamStats!$J$2:$J$209,MatchTeamStats!$F$2:$F$209,$A14) -> 10 | J14: =SUMIFS(MatchTeamStats!$K$2:$K$209,MatchTeamStats!$F$2:$F$209,$A14) -> 4 | K14: =I14-J14 -> 6 | L14: =SUMIFS(MatchTeamStats!$V$2:$V$209,MatchTeamStats!$F$2:$F$209,$A14) -> 10 | M14: =IFERROR(F14/E14,0) -> 0.6 | O14: Ranked by goals; row order is a fixed snapshot, goal counts recalc live. Source: Goals. | V14: 7 | W14: =IFERROR(INDEX(Stadiums!$B$2:$B$17,MATCH($V14,Stadiums!$A$2:$A$17,0)),"") -> Boston Stadium | X14: =IFERROR(INDEX(Stadiums!$C$2:$C$17,MATCH($V14,Stadiums!$A$2:$A$17,0)),"") -> Foxborough, Massachusetts | Y14: =COUNTIF(Matches!$E$2:$E$105,$V14) -> 7 | Z14: =SUMIFS(Matches!$P$2:$P$105,Matches!$E$2:$E$105,$V14) -> 16 | AA14: =IFERROR(Z14/Y14,0) -> 2.2857143
A15: 12 | B15: =IFERROR(INDEX(Teams!$B$2:$B$49,MATCH($A15,Teams!$A$2:$A$49,0)),"") -> USA | C15: =IFERROR(INDEX(Teams!$D$2:$D$49,MATCH($A15,Teams!$A$2:$A$49,0)),"") -> CONCACAF | D15: =IFERROR(INDEX(Teams!$E$2:$E$49,MATCH($A15,Teams!$A$2:$A$49,0)),"") -> Group D | E15: =COUNTIF(MatchTeamStats!$F$2:$F$209,$A15) -> 5 | F15: =COUNTIFS(MatchTeamStats!$F$2:$F$209,$A15,MatchTeamStats!$L$2:$L$209,"Win") -> 3 | G15: =COUNTIFS(MatchTeamStats!$F$2:$F$209,$A15,MatchTeamStats!$L$2:$L$209,"Draw") -> 0 | H15: =COUNTIFS(MatchTeamStats!$F$2:$F$209,$A15,MatchTeamStats!$L$2:$L$209,"Loss") -> 2 | I15: =SUMIFS(MatchTeamStats!$J$2:$J$209,MatchTeamStats!$F$2:$F$209,$A15) -> 11 | J15: =SUMIFS(MatchTeamStats!$K$2:$K$209,MatchTeamStats!$F$2:$F$209,$A15) -> 8 | K15: =I15-J15 -> 3 | L15: =SUMIFS(MatchTeamStats!$V$2:$V$209,MatchTeamStats!$F$2:$F$209,$A15) -> 9 | M15: =IFERROR(F15/E15,0) -> 0.6 | O15: Rank | P15: PlayerID | Q15: Player | R15: Team | S15: Position | T15: Goals | V15: 1 | W15: =IFERROR(INDEX(Stadiums!$B$2:$B$17,MATCH($V15,Stadiums!$A$2:$A$17,0)),"") -> Toronto Stadium | X15: =IFERROR(INDEX(Stadiums!$C$2:$C$17,MATCH($V15,Stadiums!$A$2:$A$17,0)),"") -> Toronto, Ontario | Y15: =COUNTIF(Matches!$E$2:$E$105,$V15) -> 6 | Z15: =SUMIFS(Matches!$P$2:$P$105,Matches!$E$2:$E$105,$V15) -> 15 | AA15: =IFERROR(Z15/Y15,0) -> 2.5
A16: 9 | B16: =IFERROR(INDEX(Teams!$B$2:$B$49,MATCH($A16,Teams!$A$2:$A$49,0)),"") -> Netherlands | C16: =IFERROR(INDEX(Teams!$D$2:$D$49,MATCH($A16,Teams!$A$2:$A$49,0)),"") -> UEFA | D16: =IFERROR(INDEX(Teams!$E$2:$E$49,MATCH($A16,Teams!$A$2:$A$49,0)),"") -> Group F | E16: =COUNTIF(MatchTeamStats!$F$2:$F$209,$A16) -> 4 | F16: =COUNTIFS(MatchTeamStats!$F$2:$F$209,$A16,MatchTeamStats!$L$2:$L$209,"Win") -> 2 | G16: =COUNTIFS(MatchTeamStats!$F$2:$F$209,$A16,MatchTeamStats!$L$2:$L$209,"Draw") -> 2 | H16: =COUNTIFS(MatchTeamStats!$F$2:$F$209,$A16,MatchTeamStats!$L$2:$L$209,"Loss") -> 0 | I16: =SUMIFS(MatchTeamStats!$J$2:$J$209,MatchTeamStats!$F$2:$F$209,$A16) -> 11 | J16: =SUMIFS(MatchTeamStats!$K$2:$K$209,MatchTeamStats!$F$2:$F$209,$A16) -> 5 | K16: =I16-J16 -> 6 | L16: =SUMIFS(MatchTeamStats!$V$2:$V$209,MatchTeamStats!$F$2:$F$209,$A16) -> 8 | M16: =IFERROR(F16/E16,0) -> 0.5 | O16: 1 | P16: 478 | Q16: =IFERROR(INDEX(Players!$B$2:$B$1249,MATCH($P16,Players!$A$2:$A$1249,0)),"") -> Kylian Mbappe | R16: =IFERROR(INDEX(Players!$D$2:$D$1249,MATCH($P16,Players!$A$2:$A$1249,0)),"") -> France | S16: =IFERROR(INDEX(Players!$E$2:$E$1249,MATCH($P16,Players!$A$2:$A$1249,0)),"") -> FW | T16: =COUNTIF(Goals!$C$2:$C$309,$P16) -> 10 | V16: 14 | W16: =IFERROR(INDEX(Stadiums!$B$2:$B$17,MATCH($V16,Stadiums!$A$2:$A$17,0)),"") -> Philadelphia Stadium | X16: =IFERROR(INDEX(Stadiums!$C$2:$C$17,MATCH($V16,Stadiums!$A$2:$A$17,0)),"") -> Philadelphia, Pennsylvania | Y16: =COUNTIF(Matches!$E$2:$E$105,$V16) -> 6 | Z16: =SUMIFS(Matches!$P$2:$P$105,Matches!$E$2:$E$105,$V16) -> 13 | AA16: =IFERROR(Z16/Y16,0) -> 2.1666667
A17: 23 | B17: =IFERROR(INDEX(Teams!$B$2:$B$49,MATCH($A17,Teams!$A$2:$A$49,0)),"") -> Portugal | C17: =IFERROR(INDEX(Teams!$D$2:$D$49,MATCH($A17,Teams!$A$2:$A$49,0)),"") -> UEFA | D17: =IFERROR(INDEX(Teams!$E$2:$E$49,MATCH($A17,Teams!$A$2:$A$49,0)),"") -> Group K | E17: =COUNTIF(MatchTeamStats!$F$2:$F$209,$A17) -> 5 | F17: =COUNTIFS(MatchTeamStats!$F$2:$F$209,$A17,MatchTeamStats!$L$2:$L$209,"Win") -> 2 | G17: =COUNTIFS(MatchTeamStats!$F$2:$F$209,$A17,MatchTeamStats!$L$2:$L$209,"Draw") -> 2 | H17: =COUNTIFS(MatchTeamStats!$F$2:$F$209,$A17,MatchTeamStats!$L$2:$L$209,"Loss") -> 1 | I17: =SUMIFS(MatchTeamStats!$J$2:$J$209,MatchTeamStats!$F$2:$F$209,$A17) -> 8 | J17: =SUMIFS(MatchTeamStats!$K$2:$K$209,MatchTeamStats!$F$2:$F$209,$A17) -> 3 | K17: =I17-J17 -> 5 | L17: =SUMIFS(MatchTeamStats!$V$2:$V$209,MatchTeamStats!$F$2:$F$209,$A17) -> 8 | M17: =IFERROR(F17/E17,0) -> 0.4 | O17: 2 | P17: 36 | Q17: =IFERROR(INDEX(Players!$B$2:$B$1249,MATCH($P17,Players!$A$2:$A$1249,0)),"") -> Lionel Messi | R17: =IFERROR(INDEX(Players!$D$2:$D$1249,MATCH($P17,Players!$A$2:$A$1249,0)),"") -> Argentina | S17: =IFERROR(INDEX(Players!$E$2:$E$1249,MATCH($P17,Players!$A$2:$A$1249,0)),"") -> FW | T17: =COUNTIF(Goals!$C$2:$C$309,$P17) -> 8 | V17: 5 | W17: =IFERROR(INDEX(Stadiums!$B$2:$B$17,MATCH($V17,Stadiums!$A$2:$A$17,0)),"") -> Estadio Monterrey | X17: =IFERROR(INDEX(Stadiums!$C$2:$C$17,MATCH($V17,Stadiums!$A$2:$A$17,0)),"") -> Guadalupe, Nuevo Leon | Y17: =COUNTIF(Matches!$E$2:$E$105,$V17) -> 4 | Z17: =SUMIFS(Matches!$P$2:$P$105,Matches!$E$2:$E$105,$V17) -> 13 | AA17: =IFERROR(Z17/Y17,0) -> 3.25
A18: 7 | B18: =IFERROR(INDEX(Teams!$B$2:$B$49,MATCH($A18,Teams!$A$2:$A$49,0)),"") -> Germany | C18: =IFERROR(INDEX(Teams!$D$2:$D$49,MATCH($A18,Teams!$A$2:$A$49,0)),"") -> UEFA | D18: =IFERROR(INDEX(Teams!$E$2:$E$49,MATCH($A18,Teams!$A$2:$A$49,0)),"") -> Group E | E18: =COUNTIF(MatchTeamStats!$F$2:$F$209,$A18) -> 4 | F18: =COUNTIFS(MatchTeamStats!$F$2:$F$209,$A18,MatchTeamStats!$L$2:$L$209,"Win") -> 2 | G18: =COUNTIFS(MatchTeamStats!$F$2:$F$209,$A18,MatchTeamStats!$L$2:$L$209,"Draw") -> 1 | H18: =COUNTIFS(MatchTeamStats!$F$2:$F$209,$A18,MatchTeamStats!$L$2:$L$209,"Loss") -> 1 | I18: =SUMIFS(MatchTeamStats!$J$2:$J$209,MatchTeamStats!$F$2:$F$209,$A18) -> 11 | J18: =SUMIFS(MatchTeamStats!$K$2:$K$209,MatchTeamStats!$F$2:$F$209,$A18) -> 5 | K18: =I18-J18 -> 6 | L18: =SUMIFS(MatchTeamStats!$V$2:$V$209,MatchTeamStats!$F$2:$F$209,$A18) -> 7 | M18: =IFERROR(F18/E18,0) -> 0.5 | O18: 3 | P18: 452 | Q18: =IFERROR(INDEX(Players!$B$2:$B$1249,MATCH($P18,Players!$A$2:$A$1249,0)),"") -> Jude Bellingham | R18: =IFERROR(INDEX(Players!$D$2:$D$1249,MATCH($P18,Players!$A$2:$A$1249,0)),"") -> England | S18: =IFERROR(INDEX(Players!$E$2:$E$1249,MATCH($P18,Players!$A$2:$A$1249,0)),"") -> MF | T18: =COUNTIF(Goals!$C$2:$C$309,$P18) -> 7 | V18: 15 | W18: =IFERROR(INDEX(Stadiums!$B$2:$B$17,MATCH($V18,Stadiums!$A$2:$A$17,0)),"") -> San Francisco Bay Area Stadium | X18: =IFERROR(INDEX(Stadiums!$C$2:$C$17,MATCH($V18,Stadiums!$A$2:$A$17,0)),"") -> Santa Clara, California | Y18: =COUNTIF(Matches!$E$2:$E$105,$V18) -> 6 | Z18: =SUMIFS(Matches!$P$2:$P$105,Matches!$E$2:$E$105,$V18) -> 12 | AA18: =IFERROR(Z18/Y18,0) -> 2
A19: 16 | B19: =IFERROR(INDEX(Teams!$B$2:$B$49,MATCH($A19,Teams!$A$2:$A$49,0)),"") -> Canada | C19: =IFERROR(INDEX(Teams!$D$2:$D$49,MATCH($A19,Teams!$A$2:$A$49,0)),"") -> CONCACAF | D19: =IFERROR(INDEX(Teams!$E$2:$E$49,MATCH($A19,Teams!$A$2:$A$49,0)),"") -> Group B | E19: =COUNTIF(MatchTeamStats!$F$2:$F$209,$A19) -> 5 | F19: =COUNTIFS(MatchTeamStats!$F$2:$F$209,$A19,MatchTeamStats!$L$2:$L$209,"Win") -> 2 | G19: =COUNTIFS(MatchTeamStats!$F$2:$F$209,$A19,MatchTeamStats!$L$2:$L$209,"Draw") -> 1 | H19: =COUNTIFS(MatchTeamStats!$F$2:$F$209,$A19,MatchTeamStats!$L$2:$L$209,"Loss") -> 2 | I19: =SUMIFS(MatchTeamStats!$J$2:$J$209,MatchTeamStats!$F$2:$F$209,$A19) -> 9 | J19: =SUMIFS(MatchTeamStats!$K$2:$K$209,MatchTeamStats!$F$2:$F$209,$A19) -> 6 | K19: =I19-J19 -> 3 | L19: =SUMIFS(MatchTeamStats!$V$2:$V$209,MatchTeamStats!$F$2:$F$209,$A19) -> 7 | M19: =IFERROR(F19/E19,0) -> 0.4 | O19: 4 | P19: 815 | Q19: =IFERROR(INDEX(Players!$B$2:$B$1249,MATCH($P19,Players!$A$2:$A$1249,0)),"") -> Erling Haaland | R19: =IFERROR(INDEX(Players!$D$2:$D$1249,MATCH($P19,Players!$A$2:$A$1249,0)),"") -> Norway | S19: =IFERROR(INDEX(Players!$E$2:$E$1249,MATCH($P19,Players!$A$2:$A$1249,0)),"") -> FW | T19: =COUNTIF(Goals!$C$2:$C$309,$P19) -> 7 | V19: 4 | W19: =IFERROR(INDEX(Stadiums!$B$2:$B$17,MATCH($V19,Stadiums!$A$2:$A$17,0)),"") -> Guadalajara Stadium | X19: =IFERROR(INDEX(Stadiums!$C$2:$C$17,MATCH($V19,Stadiums!$A$2:$A$17,0)),"") -> Zapopan, Jalisco | Y19: =COUNTIF(Matches!$E$2:$E$105,$V19) -> 4 | Z19: =SUMIFS(Matches!$P$2:$P$105,Matches!$E$2:$E$105,$V19) -> 6 | AA19: =IFERROR(Z19/Y19,0) -> 1.5
A20: 17 | B20: =IFERROR(INDEX(Teams!$B$2:$B$49,MATCH($A20,Teams!$A$2:$A$49,0)),"") -> Côte d'Ivoire | C20: =IFERROR(INDEX(Teams!$D$2:$D$49,MATCH($A20,Teams!$A$2:$A$49,0)),"") -> CAF | D20: =IFERROR(INDEX(Teams!$E$2:$E$49,MATCH($A20,Teams!$A$2:$A$49,0)),"") -> Group E | E20: =COUNTIF(MatchTeamStats!$F$2:$F$209,$A20) -> 4 | F20: =COUNTIFS(MatchTeamStats!$F$2:$F$209,$A20,MatchTeamStats!$L$2:$L$209,"Win") -> 2 | G20: =COUNTIFS(MatchTeamStats!$F$2:$F$209,$A20,MatchTeamStats!$L$2:$L$209,"Draw") -> 0 | H20: =COUNTIFS(MatchTeamStats!$F$2:$F$209,$A20,MatchTeamStats!$L$2:$L$209,"Loss") -> 2 | I20: =SUMIFS(MatchTeamStats!$J$2:$J$209,MatchTeamStats!$F$2:$F$209,$A20) -> 5 | J20: =SUMIFS(MatchTeamStats!$K$2:$K$209,MatchTeamStats!$F$2:$F$209,$A20) -> 4 | K20: =I20-J20 -> 1 | L20: =SUMIFS(MatchTeamStats!$V$2:$V$209,MatchTeamStats!$F$2:$F$209,$A20) -> 6 | M20: =IFERROR(F20/E20,0) -> 0.5 | O20: 5 | P20: 475 | Q20: =IFERROR(INDEX(Players!$B$2:$B$1249,MATCH($P20,Players!$A$2:$A$1249,0)),"") -> Ousmane Dembele | R20: =IFERROR(INDEX(Players!$D$2:$D$1249,MATCH($P20,Players!$A$2:$A$1249,0)),"") -> France | S20: =IFERROR(INDEX(Players!$E$2:$E$1249,MATCH($P20,Players!$A$2:$A$1249,0)),"") -> FW | T20: =COUNTIF(Goals!$C$2:$C$309,$P20) -> 6
A21: 19 | B21: =IFERROR(INDEX(Teams!$B$2:$B$49,MATCH($A21,Teams!$A$2:$A$49,0)),"") -> Egypt | C21: =IFERROR(INDEX(Teams!$D$2:$D$49,MATCH($A21,Teams!$A$2:$A$49,0)),"") -> CAF | D21: =IFERROR(INDEX(Teams!$E$2:$E$49,MATCH($A21,Teams!$A$2:$A$49,0)),"") -> Group G | E21: =COUNTIF(MatchTeamStats!$F$2:$F$209,$A21) -> 5 | F21: =COUNTIFS(MatchTeamStats!$F$2:$F$209,$A21,MatchTeamStats!$L$2:$L$209,"Win") -> 1 | G21: =COUNTIFS(MatchTeamStats!$F$2:$F$209,$A21,MatchTeamStats!$L$2:$L$209,"Draw") -> 3 | H21: =COUNTIFS(MatchTeamStats!$F$2:$F$209,$A21,MatchTeamStats!$L$2:$L$209,"Loss") -> 1 | I21: =SUMIFS(MatchTeamStats!$J$2:$J$209,MatchTeamStats!$F$2:$F$209,$A21) -> 8 | J21: =SUMIFS(MatchTeamStats!$K$2:$K$209,MatchTeamStats!$F$2:$F$209,$A21) -> 7 | K21: =I21-J21 -> 1 | L21: =SUMIFS(MatchTeamStats!$V$2:$V$209,MatchTeamStats!$F$2:$F$209,$A21) -> 6 | M21: =IFERROR(F21/E21,0) -> 0.2 | O21: 6 | P21: 451 | Q21: =IFERROR(INDEX(Players!$B$2:$B$1249,MATCH($P21,Players!$A$2:$A$1249,0)),"") -> Harry Kane | R21: =IFERROR(INDEX(Players!$D$2:$D$1249,MATCH($P21,Players!$A$2:$A$1249,0)),"") -> England | S21: =IFERROR(INDEX(Players!$E$2:$E$1249,MATCH($P21,Players!$A$2:$A$1249,0)),"") -> FW | T21: =COUNTIF(Goals!$C$2:$C$309,$P21) -> 6
A22: 18 | B22: =IFERROR(INDEX(Teams!$B$2:$B$49,MATCH($A22,Teams!$A$2:$A$49,0)),"") -> Croatia | C22: =IFERROR(INDEX(Teams!$D$2:$D$49,MATCH($A22,Teams!$A$2:$A$49,0)),"") -> UEFA | D22: =IFERROR(INDEX(Teams!$E$2:$E$49,MATCH($A22,Teams!$A$2:$A$49,0)),"") -> Group L | E22: =COUNTIF(MatchTeamStats!$F$2:$F$209,$A22) -> 4 | F22: =COUNTIFS(MatchTeamStats!$F$2:$F$209,$A22,MatchTeamStats!$L$2:$L$209,"Win") -> 2 | G22: =COUNTIFS(MatchTeamStats!$F$2:$F$209,$A22,MatchTeamStats!$L$2:$L$209,"Draw") -> 0 | H22: =COUNTIFS(MatchTeamStats!$F$2:$F$209,$A22,MatchTeamStats!$L$2:$L$209,"Loss") -> 2 | I22: =SUMIFS(MatchTeamStats!$J$2:$J$209,MatchTeamStats!$F$2:$F$209,$A22) -> 6 | J22: =SUMIFS(MatchTeamStats!$K$2:$K$209,MatchTeamStats!$F$2:$F$209,$A22) -> 7 | K22: =I22-J22 -> -1 | L22: =SUMIFS(MatchTeamStats!$V$2:$V$209,MatchTeamStats!$F$2:$F$209,$A22) -> 6 | M22: =IFERROR(F22/E22,0) -> 0.5 | O22: 7 | P22: 1061 | Q22: =IFERROR(INDEX(Players!$B$2:$B$1249,MATCH($P22,Players!$A$2:$A$1249,0)),"") -> Mikel Oyarzabal | R22: =IFERROR(INDEX(Players!$D$2:$D$1249,MATCH($P22,Players!$A$2:$A$1249,0)),"") -> Spain | S22: =IFERROR(INDEX(Players!$E$2:$E$1249,MATCH($P22,Players!$A$2:$A$1249,0)),"") -> FW | T22: =COUNTIF(Goals!$C$2:$C$309,$P22) -> 5 | V22: Confederation Summary
A23: 20 | B23: =IFERROR(INDEX(Teams!$B$2:$B$49,MATCH($A23,Teams!$A$2:$A$49,0)),"") -> Japan | C23: =IFERROR(INDEX(Teams!$D$2:$D$49,MATCH($A23,Teams!$A$2:$A$49,0)),"") -> AFC | D23: =IFERROR(INDEX(Teams!$E$2:$E$49,MATCH($A23,Teams!$A$2:$A$49,0)),"") -> Group F | E23: =COUNTIF(MatchTeamStats!$F$2:$F$209,$A23) -> 4 | F23: =COUNTIFS(MatchTeamStats!$F$2:$F$209,$A23,MatchTeamStats!$L$2:$L$209,"Win") -> 1 | G23: =COUNTIFS(MatchTeamStats!$F$2:$F$209,$A23,MatchTeamStats!$L$2:$L$209,"Draw") -> 2 | H23: =COUNTIFS(MatchTeamStats!$F$2:$F$209,$A23,MatchTeamStats!$L$2:$L$209,"Loss") -> 1 | I23: =SUMIFS(MatchTeamStats!$J$2:$J$209,MatchTeamStats!$F$2:$F$209,$A23) -> 8 | J23: =SUMIFS(MatchTeamStats!$K$2:$K$209,MatchTeamStats!$F$2:$F$209,$A23) -> 5 | K23: =I23-J23 -> 3 | L23: =SUMIFS(MatchTeamStats!$V$2:$V$209,MatchTeamStats!$F$2:$F$209,$A23) -> 5 | M23: =IFERROR(F23/E23,0) -> 0.25 | O23: 8 | P23: 718 | Q23: =IFERROR(INDEX(Players!$B$2:$B$1249,MATCH($P23,Players!$A$2:$A$1249,0)),"") -> Julian Quinones | R23: =IFERROR(INDEX(Players!$D$2:$D$1249,MATCH($P23,Players!$A$2:$A$1249,0)),"") -> Mexico | S23: =IFERROR(INDEX(Players!$E$2:$E$1249,MATCH($P23,Players!$A$2:$A$1249,0)),"") -> FW | T23: =COUNTIF(Goals!$C$2:$C$309,$P23) -> 4 | V23: Aggregated from Team Performance Summary (this sheet).
A24: 13 | B24: =IFERROR(INDEX(Teams!$B$2:$B$49,MATCH($A24,Teams!$A$2:$A$49,0)),"") -> Australia | C24: =IFERROR(INDEX(Teams!$D$2:$D$49,MATCH($A24,Teams!$A$2:$A$49,0)),"") -> AFC | D24: =IFERROR(INDEX(Teams!$E$2:$E$49,MATCH($A24,Teams!$A$2:$A$49,0)),"") -> Group D | E24: =COUNTIF(MatchTeamStats!$F$2:$F$209,$A24) -> 4 | F24: =COUNTIFS(MatchTeamStats!$F$2:$F$209,$A24,MatchTeamStats!$L$2:$L$209,"Win") -> 1 | G24: =COUNTIFS(MatchTeamStats!$F$2:$F$209,$A24,MatchTeamStats!$L$2:$L$209,"Draw") -> 2 | H24: =COUNTIFS(MatchTeamStats!$F$2:$F$209,$A24,MatchTeamStats!$L$2:$L$209,"Loss") -> 1 | I24: =SUMIFS(MatchTeamStats!$J$2:$J$209,MatchTeamStats!$F$2:$F$209,$A24) -> 3 | J24: =SUMIFS(MatchTeamStats!$K$2:$K$209,MatchTeamStats!$F$2:$F$209,$A24) -> 3 | K24: =I24-J24 -> 0 | L24: =SUMIFS(MatchTeamStats!$V$2:$V$209,MatchTeamStats!$F$2:$F$209,$A24) -> 5 | M24: =IFERROR(F24/E24,0) -> 0.25 | O24: 9 | P24: 1006 | Q24: =IFERROR(INDEX(Players!$B$2:$B$1249,MATCH($P24,Players!$A$2:$A$1249,0)),"") -> Ismaila Sarr | R24: =IFERROR(INDEX(Players!$D$2:$D$1249,MATCH($P24,Players!$A$2:$A$1249,0)),"") -> Senegal | S24: =IFERROR(INDEX(Players!$E$2:$E$1249,MATCH($P24,Players!$A$2:$A$1249,0)),"") -> FW | T24: =COUNTIF(Goals!$C$2:$C$309,$P24) -> 4 | V24: Confederation | W24: Teams | X24: Total Wins | Y24: Total Goals For | Z24: Total Points
A25: 32 | B25: =IFERROR(INDEX(Teams!$B$2:$B$49,MATCH($A25,Teams!$A$2:$A$49,0)),"") -> Paraguay | C25: =IFERROR(INDEX(Teams!$D$2:$D$49,MATCH($A25,Teams!$A$2:$A$49,0)),"") -> CONMEBOL | D25: =IFERROR(INDEX(Teams!$E$2:$E$49,MATCH($A25,Teams!$A$2:$A$49,0)),"") -> Group D | E25: =COUNTIF(MatchTeamStats!$F$2:$F$209,$A25) -> 5 | F25: =COUNTIFS(MatchTeamStats!$F$2:$F$209,$A25,MatchTeamStats!$L$2:$L$209,"Win") -> 1 | G25: =COUNTIFS(MatchTeamStats!$F$2:$F$209,$A25,MatchTeamStats!$L$2:$L$209,"Draw") -> 2 | H25: =COUNTIFS(MatchTeamStats!$F$2:$F$209,$A25,MatchTeamStats!$L$2:$L$209,"Loss") -> 2 | I25: =SUMIFS(MatchTeamStats!$J$2:$J$209,MatchTeamStats!$F$2:$F$209,$A25) -> 3 | J25: =SUMIFS(MatchTeamStats!$K$2:$K$209,MatchTeamStats!$F$2:$F$209,$A25) -> 6 | K25: =I25-J25 -> -3 | L25: =SUMIFS(MatchTeamStats!$V$2:$V$209,MatchTeamStats!$F$2:$F$209,$A25) -> 5 | M25: =IFERROR(F25/E25,0) -> 0.2 | O25: 10 | P25: 163 | Q25: =IFERROR(INDEX(Players!$B$2:$B$1249,MATCH($P25,Players!$A$2:$A$1249,0)),"") -> Vinicius Junior | R25: =IFERROR(INDEX(Players!$D$2:$D$1249,MATCH($P25,Players!$A$2:$A$1249,0)),"") -> Brazil | S25: =IFERROR(INDEX(Players!$E$2:$E$1249,MATCH($P25,Players!$A$2:$A$1249,0)),"") -> FW | T25: =COUNTIF(Goals!$C$2:$C$309,$P25) -> 4 | V25: UEFA | W25: =COUNTIF($C$4:$C$51,$V25) -> 16 | X25: =SUMIF($C$4:$C$51,$V25,$F$4:$F$51) -> 42 | Y25: =SUMIF($C$4:$C$51,$V25,$I$4:$I$51) -> 151 | Z25: =SUMIF($C$4:$C$51,$V25,$L$4:$L$51) -> 141
A26: 27 | B26: =IFERROR(INDEX(Teams!$B$2:$B$49,MATCH($A26,Teams!$A$2:$A$49,0)),"") -> Congo DR | C26: =IFERROR(INDEX(Teams!$D$2:$D$49,MATCH($A26,Teams!$A$2:$A$49,0)),"") -> CAF | D26: =IFERROR(INDEX(Teams!$E$2:$E$49,MATCH($A26,Teams!$A$2:$A$49,0)),"") -> Group K | E26: =COUNTIF(MatchTeamStats!$F$2:$F$209,$A26) -> 4 | F26: =COUNTIFS(MatchTeamStats!$F$2:$F$209,$A26,MatchTeamStats!$L$2:$L$209,"Win") -> 1 | G26: =COUNTIFS(MatchTeamStats!$F$2:$F$209,$A26,MatchTeamStats!$L$2:$L$209,"Draw") -> 1 | H26: =COUNTIFS(MatchTeamStats!$F$2:$F$209,$A26,MatchTeamStats!$L$2:$L$209,"Loss") -> 2 | I26: =SUMIFS(MatchTeamStats!$J$2:$J$209,MatchTeamStats!$F$2:$F$209,$A26) -> 5 | J26: =SUMIFS(MatchTeamStats!$K$2:$K$209,MatchTeamStats!$F$2:$F$209,$A26) -> 5 | K26: =I26-J26 -> 0 | L26: =SUMIFS(MatchTeamStats!$V$2:$V$209,MatchTeamStats!$F$2:$F$209,$A26) -> 4 | M26: =IFERROR(F26/E26,0) -> 0.25 | O26: 11 | P26: 121 | Q26: =IFERROR(INDEX(Players!$B$2:$B$1249,MATCH($P26,Players!$A$2:$A$1249,0)),"") -> Charles De Ketelaere | R26: =IFERROR(INDEX(Players!$D$2:$D$1249,MATCH($P26,Players!$A$2:$A$1249,0)),"") -> Belgium | S26: =IFERROR(INDEX(Players!$E$2:$E$1249,MATCH($P26,Players!$A$2:$A$1249,0)),"") -> FW | T26: =COUNTIF(Goals!$C$2:$C$309,$P26) -> 3 | V26: CAF | W26: =COUNTIF($C$4:$C$51,$V26) -> 10 | X26: =SUMIF($C$4:$C$51,$V26,$F$4:$F$51) -> 11 | Y26: =SUMIF($C$4:$C$51,$V26,$I$4:$I$51) -> 53 | Z26: =SUMIF($C$4:$C$51,$V26,$L$4:$L$51) -> 45
A27: 29 | B27: =IFERROR(INDEX(Teams!$B$2:$B$49,MATCH($A27,Teams!$A$2:$A$49,0)),"") -> Ghana | C27: =IFERROR(INDEX(Teams!$D$2:$D$49,MATCH($A27,Teams!$A$2:$A$49,0)),"") -> CAF | D27: =IFERROR(INDEX(Teams!$E$2:$E$49,MATCH($A27,Teams!$A$2:$A$49,0)),"") -> Group L | E27: =COUNTIF(MatchTeamStats!$F$2:$F$209,$A27) -> 4 | F27: =COUNTIFS(MatchTeamStats!$F$2:$F$209,$A27,MatchTeamStats!$L$2:$L$209,"Win") -> 1 | G27: =COUNTIFS(MatchTeamStats!$F$2:$F$209,$A27,MatchTeamStats!$L$2:$L$209,"Draw") -> 1 | H27: =COUNTIFS(MatchTeamStats!$F$2:$F$209,$A27,MatchTeamStats!$L$2:$L$209,"Loss") -> 2 | I27: =SUMIFS(MatchTeamStats!$J$2:$J$209,MatchTeamStats!$F$2:$F$209,$A27) -> 2 | J27: =SUMIFS(MatchTeamStats!$K$2:$K$209,MatchTeamStats!$F$2:$F$209,$A27) -> 3 | K27: =I27-J27 -> -1 | L27: =SUMIFS(MatchTeamStats!$V$2:$V$209,MatchTeamStats!$F$2:$F$209,$A27) -> 4 | M27: =IFERROR(F27/E27,0) -> 0.25 | O27: 12 | P27: 113 | Q27: =IFERROR(INDEX(Players!$B$2:$B$1249,MATCH($P27,Players!$A$2:$A$1249,0)),"") -> Romelu Lukaku | R27: =IFERROR(INDEX(Players!$D$2:$D$1249,MATCH($P27,Players!$A$2:$A$1249,0)),"") -> Belgium | S27: =IFERROR(INDEX(Players!$E$2:$E$1249,MATCH($P27,Players!$A$2:$A$1249,0)),"") -> FW | T27: =COUNTIF(Goals!$C$2:$C$309,$P27) -> 3 | V27: AFC | W27: =COUNTIF($C$4:$C$51,$V27) -> 9 | X27: =SUMIF($C$4:$C$51,$V27,$F$4:$F$51) -> 3 | Y27: =SUMIF($C$4:$C$51,$V27,$I$4:$I$51) -> 25 | Z27: =SUMIF($C$4:$C$51,$V27,$L$4:$L$51) -> 19
A28: 24 | B28: =IFERROR(INDEX(Teams!$B$2:$B$49,MATCH($A28,Teams!$A$2:$A$49,0)),"") -> South Africa | C28: =IFERROR(INDEX(Teams!$D$2:$D$49,MATCH($A28,Teams!$A$2:$A$49,0)),"") -> CAF | D28: =IFERROR(INDEX(Teams!$E$2:$E$49,MATCH($A28,Teams!$A$2:$A$49,0)),"") -> Group A | E28: =COUNTIF(MatchTeamStats!$F$2:$F$209,$A28) -> 4 | F28: =COUNTIFS(MatchTeamStats!$F$2:$F$209,$A28,MatchTeamStats!$L$2:$L$209,"Win") -> 1 | G28: =COUNTIFS(MatchTeamStats!$F$2:$F$209,$A28,MatchTeamStats!$L$2:$L$209,"Draw") -> 1 | H28: =COUNTIFS(MatchTeamStats!$F$2:$F$209,$A28,MatchTeamStats!$L$2:$L$209,"Loss") -> 2 | I28: =SUMIFS(MatchTeamStats!$J$2:$J$209,MatchTeamStats!$F$2:$F$209,$A28) -> 2 | J28: =SUMIFS(MatchTeamStats!$K$2:$K$209,MatchTeamStats!$F$2:$F$209,$A28) -> 4 | K28: =I28-J28 -> -2 | L28: =SUMIFS(MatchTeamStats!$V$2:$V$209,MatchTeamStats!$F$2:$F$209,$A28) -> 4 | M28: =IFERROR(F28/E28,0) -> 0.25 | O28: 13 | P28: 165 | Q28: =IFERROR(INDEX(Players!$B$2:$B$1249,MATCH($P28,Players!$A$2:$A$1249,0)),"") -> Matheus Cunha | R28: =IFERROR(INDEX(Players!$D$2:$D$1249,MATCH($P28,Players!$A$2:$A$1249,0)),"") -> Brazil | S28: =IFERROR(INDEX(Players!$E$2:$E$1249,MATCH($P28,Players!$A$2:$A$1249,0)),"") -> FW | T28: =COUNTIF(Goals!$C$2:$C$309,$P28) -> 3 | V28: CONMEBOL | W28: =COUNTIF($C$4:$C$51,$V28) -> 6 | X28: =SUMIF($C$4:$C$51,$V28,$F$4:$F$51) -> 15 | Y28: =SUMIF($C$4:$C$51,$V28,$I$4:$I$51) -> 42 | Z28: =SUMIF($C$4:$C$51,$V28,$L$4:$L$51) -> 53
A29: 28 | B29: =IFERROR(INDEX(Teams!$B$2:$B$49,MATCH($A29,Teams!$A$2:$A$49,0)),"") -> Ecuador | C29: =IFERROR(INDEX(Teams!$D$2:$D$49,MATCH($A29,Teams!$A$2:$A$49,0)),"") -> CONMEBOL | D29: =IFERROR(INDEX(Teams!$E$2:$E$49,MATCH($A29,Teams!$A$2:$A$49,0)),"") -> Group E | E29: =COUNTIF(MatchTeamStats!$F$2:$F$209,$A29) -> 4 | F29: =COUNTIFS(MatchTeamStats!$F$2:$F$209,$A29,MatchTeamStats!$L$2:$L$209,"Win") -> 1 | G29: =COUNTIFS(MatchTeamStats!$F$2:$F$209,$A29,MatchTeamStats!$L$2:$L$209,"Draw") -> 1 | H29: =COUNTIFS(MatchTeamStats!$F$2:$F$209,$A29,MatchTeamStats!$L$2:$L$209,"Loss") -> 2 | I29: =SUMIFS(MatchTeamStats!$J$2:$J$209,MatchTeamStats!$F$2:$F$209,$A29) -> 2 | J29: =SUMIFS(MatchTeamStats!$K$2:$K$209,MatchTeamStats!$F$2:$F$209,$A29) -> 4 | K29: =I29-J29 -> -2 | L29: =SUMIFS(MatchTeamStats!$V$2:$V$209,MatchTeamStats!$F$2:$F$209,$A29) -> 4 | M29: =IFERROR(F29/E29,0) -> 0.25 | O29: 14 | P29: 48 | Q29: =IFERROR(INDEX(Players!$B$2:$B$1249,MATCH($P29,Players!$A$2:$A$1249,0)),"") -> Lautaro Martinez | R29: =IFERROR(INDEX(Players!$D$2:$D$1249,MATCH($P29,Players!$A$2:$A$1249,0)),"") -> Argentina | S29: =IFERROR(INDEX(Players!$E$2:$E$1249,MATCH($P29,Players!$A$2:$A$1249,0)),"") -> FW | T29: =COUNTIF(Goals!$C$2:$C$309,$P29) -> 3 | V29: CONCACAF | W29: =COUNTIF($C$4:$C$51,$V29) -> 6 | X29: =SUMIF($C$4:$C$51,$V29,$F$4:$F$51) -> 9 | Y29: =SUMIF($C$4:$C$51,$V29,$I$4:$I$51) -> 33 | Z29: =SUMIF($C$4:$C$51,$V29,$L$4:$L$51) -> 29
A30: 14 | B30: =IFERROR(INDEX(Teams!$B$2:$B$49,MATCH($A30,Teams!$A$2:$A$49,0)),"") -> Austria | C30: =IFERROR(INDEX(Teams!$D$2:$D$49,MATCH($A30,Teams!$A$2:$A$49,0)),"") -> UEFA | D30: =IFERROR(INDEX(Teams!$E$2:$E$49,MATCH($A30,Teams!$A$2:$A$49,0)),"") -> Group J | E30: =COUNTIF(MatchTeamStats!$F$2:$F$209,$A30) -> 4 | F30: =COUNTIFS(MatchTeamStats!$F$2:$F$209,$A30,MatchTeamStats!$L$2:$L$209,"Win") -> 1 | G30: =COUNTIFS(MatchTeamStats!$F$2:$F$209,$A30,MatchTeamStats!$L$2:$L$209,"Draw") -> 1 | H30: =COUNTIFS(MatchTeamStats!$F$2:$F$209,$A30,MatchTeamStats!$L$2:$L$209,"Loss") -> 2 | I30: =SUMIFS(MatchTeamStats!$J$2:$J$209,MatchTeamStats!$F$2:$F$209,$A30) -> 6 | J30: =SUMIFS(MatchTeamStats!$K$2:$K$209,MatchTeamStats!$F$2:$F$209,$A30) -> 9 | K30: =I30-J30 -> -3 | L30: =SUMIFS(MatchTeamStats!$V$2:$V$209,MatchTeamStats!$F$2:$F$209,$A30) -> 4 | M30: =IFERROR(F30/E30,0) -> 0.25 | O30: 15 | P30: 480 | Q30: =IFERROR(INDEX(Players!$B$2:$B$1249,MATCH($P30,Players!$A$2:$A$1249,0)),"") -> Bradley Barcola | R30: =IFERROR(INDEX(Players!$D$2:$D$1249,MATCH($P30,Players!$A$2:$A$1249,0)),"") -> France | S30: =IFERROR(INDEX(Players!$E$2:$E$1249,MATCH($P30,Players!$A$2:$A$1249,0)),"") -> FW | T30: =COUNTIF(Goals!$C$2:$C$309,$P30) -> 3 | V30: OFC | W30: =COUNTIF($C$4:$C$51,$V30) -> 1 | X30: =SUMIF($C$4:$C$51,$V30,$F$4:$F$51) -> 0 | Y30: =SUMIF($C$4:$C$51,$V30,$I$4:$I$51) -> 4 | Z30: =SUMIF($C$4:$C$51,$V30,$L$4:$L$51) -> 1
A31: 26 | B31: =IFERROR(INDEX(Teams!$B$2:$B$49,MATCH($A31,Teams!$A$2:$A$49,0)),"") -> Bosnia and Herzegovina | C31: =IFERROR(INDEX(Teams!$D$2:$D$49,MATCH($A31,Teams!$A$2:$A$49,0)),"") -> UEFA | D31: =IFERROR(INDEX(Teams!$E$2:$E$49,MATCH($A31,Teams!$A$2:$A$49,0)),"") -> Group B | E31: =COUNTIF(MatchTeamStats!$F$2:$F$209,$A31) -> 4 | F31: =COUNTIFS(MatchTeamStats!$F$2:$F$209,$A31,MatchTeamStats!$L$2:$L$209,"Win") -> 1 | G31: =COUNTIFS(MatchTeamStats!$F$2:$F$209,$A31,MatchTeamStats!$L$2:$L$209,"Draw") -> 1 | H31: =COUNTIFS(MatchTeamStats!$F$2:$F$209,$A31,MatchTeamStats!$L$2:$L$209,"Loss") -> 2 | I31: =SUMIFS(MatchTeamStats!$J$2:$J$209,MatchTeamStats!$F$2:$F$209,$A31) -> 5 | J31: =SUMIFS(MatchTeamStats!$K$2:$K$209,MatchTeamStats!$F$2:$F$209,$A31) -> 8 | K31: =I31-J31 -> -3 | L31: =SUMIFS(MatchTeamStats!$V$2:$V$209,MatchTeamStats!$F$2:$F$209,$A31) -> 4 | M31: =IFERROR(F31/E31,0) -> 0.25
A32: 35 | B32: =IFERROR(INDEX(Teams!$B$2:$B$49,MATCH($A32,Teams!$A$2:$A$49,0)),"") -> Sweden | C32: =IFERROR(INDEX(Teams!$D$2:$D$49,MATCH($A32,Teams!$A$2:$A$49,0)),"") -> UEFA | D32: =IFERROR(INDEX(Teams!$E$2:$E$49,MATCH($A32,Teams!$A$2:$A$49,0)),"") -> Group F | E32: =COUNTIF(MatchTeamStats!$F$2:$F$209,$A32) -> 4 | F32: =COUNTIFS(MatchTeamStats!$F$2:$F$209,$A32,MatchTeamStats!$L$2:$L$209,"Win") -> 1 | G32: =COUNTIFS(MatchTeamStats!$F$2:$F$209,$A32,MatchTeamStats!$L$2:$L$209,"Draw") -> 1 | H32: =COUNTIFS(MatchTeamStats!$F$2:$F$209,$A32,MatchTeamStats!$L$2:$L$209,"Loss") -> 2 | I32: =SUMIFS(MatchTeamStats!$J$2:$J$209,MatchTeamStats!$F$2:$F$209,$A32) -> 7 | J32: =SUMIFS(MatchTeamStats!$K$2:$K$209,MatchTeamStats!$F$2:$F$209,$A32) -> 10 | K32: =I32-J32 -> -3 | L32: =SUMIFS(MatchTeamStats!$V$2:$V$209,MatchTeamStats!$F$2:$F$209,$A32) -> 4 | M32: =IFERROR(F32/E32,0) -> 0.25
A33: 25 | B33: =IFERROR(INDEX(Teams!$B$2:$B$49,MATCH($A33,Teams!$A$2:$A$49,0)),"") -> Algeria | C33: =IFERROR(INDEX(Teams!$D$2:$D$49,MATCH($A33,Teams!$A$2:$A$49,0)),"") -> CAF | D33: =IFERROR(INDEX(Teams!$E$2:$E$49,MATCH($A33,Teams!$A$2:$A$49,0)),"") -> Group J | E33: =COUNTIF(MatchTeamStats!$F$2:$F$209,$A33) -> 4 | F33: =COUNTIFS(MatchTeamStats!$F$2:$F$209,$A33,MatchTeamStats!$L$2:$L$209,"Win") -> 1 | G33: =COUNTIFS(MatchTeamStats!$F$2:$F$209,$A33,MatchTeamStats!$L$2:$L$209,"Draw") -> 1 | H33: =COUNTIFS(MatchTeamStats!$F$2:$F$209,$A33,MatchTeamStats!$L$2:$L$209,"Loss") -> 2 | I33: =SUMIFS(MatchTeamStats!$J$2:$J$209,MatchTeamStats!$F$2:$F$209,$A33) -> 5 | J33: =SUMIFS(MatchTeamStats!$K$2:$K$209,MatchTeamStats!$F$2:$F$209,$A33) -> 9 | K33: =I33-J33 -> -4 | L33: =SUMIFS(MatchTeamStats!$V$2:$V$209,MatchTeamStats!$F$2:$F$209,$A33) -> 4 | M33: =IFERROR(F33/E33,0) -> 0.25
A34: 34 | B34: =IFERROR(INDEX(Teams!$B$2:$B$49,MATCH($A34,Teams!$A$2:$A$49,0)),"") -> Senegal | C34: =IFERROR(INDEX(Teams!$D$2:$D$49,MATCH($A34,Teams!$A$2:$A$49,0)),"") -> CAF | D34: =IFERROR(INDEX(Teams!$E$2:$E$49,MATCH($A34,Teams!$A$2:$A$49,0)),"") -> Group I | E34: =COUNTIF(MatchTeamStats!$F$2:$F$209,$A34) -> 4 | F34: =COUNTIFS(MatchTeamStats!$F$2:$F$209,$A34,MatchTeamStats!$L$2:$L$209,"Win") -> 1 | G34: =COUNTIFS(MatchTeamStats!$F$2:$F$209,$A34,MatchTeamStats!$L$2:$L$209,"Draw") -> 0 | H34: =COUNTIFS(MatchTeamStats!$F$2:$F$209,$A34,MatchTeamStats!$L$2:$L$209,"Loss") -> 3 | I34: =SUMIFS(MatchTeamStats!$J$2:$J$209,MatchTeamStats!$F$2:$F$209,$A34) -> 10 | J34: =SUMIFS(MatchTeamStats!$K$2:$K$209,MatchTeamStats!$F$2:$F$209,$A34) -> 9 | K34: =I34-J34 -> 1 | L34: =SUMIFS(MatchTeamStats!$V$2:$V$209,MatchTeamStats!$F$2:$F$209,$A34) -> 3 | M34: =IFERROR(F34/E34,0) -> 0.25
A35: 30 | B35: =IFERROR(INDEX(Teams!$B$2:$B$49,MATCH($A35,Teams!$A$2:$A$49,0)),"") -> IR Iran | C35: =IFERROR(INDEX(Teams!$D$2:$D$49,MATCH($A35,Teams!$A$2:$A$49,0)),"") -> AFC | D35: =IFERROR(INDEX(Teams!$E$2:$E$49,MATCH($A35,Teams!$A$2:$A$49,0)),"") -> Group G | E35: =COUNTIF(MatchTeamStats!$F$2:$F$209,$A35) -> 3 | F35: =COUNTIFS(MatchTeamStats!$F$2:$F$209,$A35,MatchTeamStats!$L$2:$L$209,"Win") -> 0 | G35: =COUNTIFS(MatchTeamStats!$F$2:$F$209,$A35,MatchTeamStats!$L$2:$L$209,"Draw") -> 3 | H35: =COUNTIFS(MatchTeamStats!$F$2:$F$209,$A35,MatchTeamStats!$L$2:$L$209,"Loss") -> 0 | I35: =SUMIFS(MatchTeamStats!$J$2:$J$209,MatchTeamStats!$F$2:$F$209,$A35) -> 3 | J35: =SUMIFS(MatchTeamStats!$K$2:$K$209,MatchTeamStats!$F$2:$F$209,$A35) -> 3 | K35: =I35-J35 -> 0 | L35: =SUMIFS(MatchTeamStats!$V$2:$V$209,MatchTeamStats!$F$2:$F$209,$A35) -> 3 | M35: =IFERROR(F35/E35,0) -> 0
A36: 15 | B36: =IFERROR(INDEX(Teams!$B$2:$B$49,MATCH($A36,Teams!$A$2:$A$49,0)),"") -> Cabo Verde | C36: =IFERROR(INDEX(Teams!$D$2:$D$49,MATCH($A36,Teams!$A$2:$A$49,0)),"") -> CAF | D36: =IFERROR(INDEX(Teams!$E$2:$E$49,MATCH($A36,Teams!$A$2:$A$49,0)),"") -> Group H | E36: =COUNTIF(MatchTeamStats!$F$2:$F$209,$A36) -> 4 | F36: =COUNTIFS(MatchTeamStats!$F$2:$F$209,$A36,MatchTeamStats!$L$2:$L$209,"Win") -> 0 | G36: =COUNTIFS(MatchTeamStats!$F$2:$F$209,$A36,MatchTeamStats!$L$2:$L$209,"Draw") -> 3 | H36: =COUNTIFS(MatchTeamStats!$F$2:$F$209,$A36,MatchTeamStats!$L$2:$L$209,"Loss") -> 1 | I36: =SUMIFS(MatchTeamStats!$J$2:$J$209,MatchTeamStats!$F$2:$F$209,$A36) -> 4 | J36: =SUMIFS(MatchTeamStats!$K$2:$K$209,MatchTeamStats!$F$2:$F$209,$A36) -> 5 | K36: =I36-J36 -> -1 | L36: =SUMIFS(MatchTeamStats!$V$2:$V$209,MatchTeamStats!$F$2:$F$209,$A36) -> 3 | M36: =IFERROR(F36/E36,0) -> 0
A37: 31 | B37: =IFERROR(INDEX(Teams!$B$2:$B$49,MATCH($A37,Teams!$A$2:$A$49,0)),"") -> Korea Republic | C37: =IFERROR(INDEX(Teams!$D$2:$D$49,MATCH($A37,Teams!$A$2:$A$49,0)),"") -> AFC | D37: =IFERROR(INDEX(Teams!$E$2:$E$49,MATCH($A37,Teams!$A$2:$A$49,0)),"") -> Group A | E37: =COUNTIF(MatchTeamStats!$F$2:$F$209,$A37) -> 3 | F37: =COUNTIFS(MatchTeamStats!$F$2:$F$209,$A37,MatchTeamStats!$L$2:$L$209,"Win") -> 1 | G37: =COUNTIFS(MatchTeamStats!$F$2:$F$209,$A37,MatchTeamStats!$L$2:$L$209,"Draw") -> 0 | H37: =COUNTIFS(MatchTeamStats!$F$2:$F$209,$A37,MatchTeamStats!$L$2:$L$209,"Loss") -> 2 | I37: =SUMIFS(MatchTeamStats!$J$2:$J$209,MatchTeamStats!$F$2:$F$209,$A37) -> 2 | J37: =SUMIFS(MatchTeamStats!$K$2:$K$209,MatchTeamStats!$F$2:$F$209,$A37) -> 3 | K37: =I37-J37 -> -1 | L37: =SUMIFS(MatchTeamStats!$V$2:$V$209,MatchTeamStats!$F$2:$F$209,$A37) -> 3 | M37: =IFERROR(F37/E37,0) -> 0.33333333
A38: 47 | B38: =IFERROR(INDEX(Teams!$B$2:$B$49,MATCH($A38,Teams!$A$2:$A$49,0)),"") -> Türkiye | C38: =IFERROR(INDEX(Teams!$D$2:$D$49,MATCH($A38,Teams!$A$2:$A$49,0)),"") -> UEFA | D38: =IFERROR(INDEX(Teams!$E$2:$E$49,MATCH($A38,Teams!$A$2:$A$49,0)),"") -> Group D | E38: =COUNTIF(MatchTeamStats!$F$2:$F$209,$A38) -> 3 | F38: =COUNTIFS(MatchTeamStats!$F$2:$F$209,$A38,MatchTeamStats!$L$2:$L$209,"Win") -> 1 | G38: =COUNTIFS(MatchTeamStats!$F$2:$F$209,$A38,MatchTeamStats!$L$2:$L$209,"Draw") -> 0 | H38: =COUNTIFS(MatchTeamStats!$F$2:$F$209,$A38,MatchTeamStats!$L$2:$L$209,"Loss") -> 2 | I38: =SUMIFS(MatchTeamStats!$J$2:$J$209,MatchTeamStats!$F$2:$F$209,$A38) -> 3 | J38: =SUMIFS(MatchTeamStats!$K$2:$K$209,MatchTeamStats!$F$2:$F$209,$A38) -> 5 | K38: =I38-J38 -> -2 | L38: =SUMIFS(MatchTeamStats!$V$2:$V$209,MatchTeamStats!$F$2:$F$209,$A38) -> 3 | M38: =IFERROR(F38/E38,0) -> 0.33333333
A39: 33 | B39: =IFERROR(INDEX(Teams!$B$2:$B$49,MATCH($A39,Teams!$A$2:$A$49,0)),"") -> Scotland | C39: =IFERROR(INDEX(Teams!$D$2:$D$49,MATCH($A39,Teams!$A$2:$A$49,0)),"") -> UEFA | D39: =IFERROR(INDEX(Teams!$E$2:$E$49,MATCH($A39,Teams!$A$2:$A$49,0)),"") -> Group C | E39: =COUNTIF(MatchTeamStats!$F$2:$F$209,$A39) -> 3 | F39: =COUNTIFS(MatchTeamStats!$F$2:$F$209,$A39,MatchTeamStats!$L$2:$L$209,"Win") -> 1 | G39: =COUNTIFS(MatchTeamStats!$F$2:$F$209,$A39,MatchTeamStats!$L$2:$L$209,"Draw") -> 0 | H39: =COUNTIFS(MatchTeamStats!$F$2:$F$209,$A39,MatchTeamStats!$L$2:$L$209,"Loss") -> 2 | I39: =SUMIFS(MatchTeamStats!$J$2:$J$209,MatchTeamStats!$F$2:$F$209,$A39) -> 1 | J39: =SUMIFS(MatchTeamStats!$K$2:$K$209,MatchTeamStats!$F$2:$F$209,$A39) -> 4 | K39: =I39-J39 -> -3 | L39: =SUMIFS(MatchTeamStats!$V$2:$V$209,MatchTeamStats!$F$2:$F$209,$A39) -> 3 | M39: =IFERROR(F39/E39,0) -> 0.33333333
A40: 36 | B40: =IFERROR(INDEX(Teams!$B$2:$B$49,MATCH($A40,Teams!$A$2:$A$49,0)),"") -> Uruguay | C40: =IFERROR(INDEX(Teams!$D$2:$D$49,MATCH($A40,Teams!$A$2:$A$49,0)),"") -> CONMEBOL | D40: =IFERROR(INDEX(Teams!$E$2:$E$49,MATCH($A40,Teams!$A$2:$A$49,0)),"") -> Group H | E40: =COUNTIF(MatchTeamStats!$F$2:$F$209,$A40) -> 3 | F40: =COUNTIFS(MatchTeamStats!$F$2:$F$209,$A40,MatchTeamStats!$L$2:$L$209,"Win") -> 0 | G40: =COUNTIFS(MatchTeamStats!$F$2:$F$209,$A40,MatchTeamStats!$L$2:$L$209,"Draw") -> 2 | H40: =COUNTIFS(MatchTeamStats!$F$2:$F$209,$A40,MatchTeamStats!$L$2:$L$209,"Loss") -> 1 | I40: =SUMIFS(MatchTeamStats!$J$2:$J$209,MatchTeamStats!$F$2:$F$209,$A40) -> 3 | J40: =SUMIFS(MatchTeamStats!$K$2:$K$209,MatchTeamStats!$F$2:$F$209,$A40) -> 4 | K40: =I40-J40 -> -1 | L40: =SUMIFS(MatchTeamStats!$V$2:$V$209,MatchTeamStats!$F$2:$F$209,$A40) -> 2 | M40: =IFERROR(F40/E40,0) -> 0
...

Sheet Teams
A1: TeamID | B1: TeamName | C1: CountryCode | D1: Confederation | E1: GroupName | F1: HostCountry
A2: 1 | B2: Argentina | C2: ARG | D2: CONMEBOL | E2: Group J
A3: 2 | B3: Belgium | C3: BEL | D3: UEFA | E3: Group G
A4: 3 | B4: Brazil | C4: BRA | D4: CONMEBOL | E4: Group C
A5: 4 | B5: Colombia | C5: COL | D5: CONMEBOL | E5: Group K
A6: 5 | B6: England | C6: ENG | D6: UEFA | E6: Group L
A7: 6 | B7: France | C7: FRA | D7: UEFA | E7: Group I
A8: 7 | B8: Germany | C8: GER | D8: UEFA | E8: Group E
A9: 8 | B9: Mexico | C9: MEX | D9: CONCACAF | E9: Group A | F9: Mexico
A10: 9 | B10: Netherlands | C10: NED | D10: UEFA | E10: Group F
A11: 10 | B11: Spain | C11: ESP | D11: UEFA | E11: Group H
A12: 11 | B12: Switzerland | C12: SUI | D12: UEFA | E12: Group B
A13: 12 | B13: USA | C13: USA | D13: CONCACAF | E13: Group D | F13: United States
A14: 13 | B14: Australia | C14: AUS | D14: AFC | E14: Group D
A15: 14 | B15: Austria | C15: AUT | D15: UEFA | E15: Group J
A16: 15 | B16: Cabo Verde | C16: CPV | D16: CAF | E16: Group H
A17: 16 | B17: Canada | C17: CAN | D17: CONCACAF | E17: Group B | F17: Canada
A18: 17 | B18: Côte d'Ivoire | C18: CIV | D18: CAF | E18: Group E
A19: 18 | B19: Croatia | C19: CRO | D19: UEFA | E19: Group L
A20: 19 | B20: Egypt | C20: EGY | D20: CAF | E20: Group G
A21: 20 | B21: Japan | C21: JPN | D21: AFC | E21: Group F
A22: 21 | B22: Morocco | C22: MAR | D22: CAF | E22: Group C
A23: 22 | B23: Norway | C23: NOR | D23: UEFA | E23: Group I
A24: 23 | B24: Portugal | C24: POR | D24: UEFA | E24: Group K
A25: 24 | B25: South Africa | C25: RSA | D25: CAF | E25: Group A
A26: 25 | B26: Algeria | C26: ALG | D26: CAF | E26: Group J
A27: 26 | B27: Bosnia and Herzegovina | C27: BIH | D27: UEFA | E27: Group B
A28: 27 | B28: Congo DR | C28: COD | D28: CAF | E28: Group K
A29: 28 | B29: Ecuador | C29: ECU | D29: CONMEBOL | E29: Group E
... A49: 48 | B49: Uzbekistan | C49: UZB | D49: AFC | E49: Group K

Sheet Matches
A1: MatchID | B1: MatchDate | C1: Stage | D1: GroupName | E1: StadiumID | F1: StadiumName | G1: Team1ID | H1: Team1Name | I1: Team2ID | J1: Team2Name | K1: Team1Goals | L1: Team2Goals | M1: WinnerTeamID | N1: WinnerName | O1: Result | P1: TotalGoals | Q1: GoalDifference
A2: 1 | B2: 2026-06-11 | C2: First Stage | D2: Group A | E2: 3 | F2: =IFERROR(INDEX(Stadiums!$B$2:$B$17,MATCH($E2,Stadiums!$A$2:$A$17,0)),"") -> Mexico City Stadium | G2: 8 | H2: =IFERROR(INDEX(Teams!$B$2:$B$49,MATCH($G2,Teams!$A$2:$A$49,0)),"") -> Mexico | I2: 24 | J2: =IFERROR(INDEX(Teams!$B$2:$B$49,MATCH($I2,Teams!$A$2:$A$49,0)),"") -> South Africa | K2: 2 | L2: 0 | M2: 8 | N2: =IFERROR(INDEX(Teams!$B$2:$B$49,MATCH($M2,Teams!$A$2:$A$49,0)),"Draw") -> Mexico | O2: W | P2: 2 | Q2: 2
A3: 2 | B3: 2026-06-11 | C3: First Stage | D3: Group A | E3: 4 | F3: =IFERROR(INDEX(Stadiums!$B$2:$B$17,MATCH($E3,Stadiums!$A$2:$A$17,0)),"") -> Guadalajara Stadium | G3: 31 | H3: =IFERROR(INDEX(Teams!$B$2:$B$49,MATCH($G3,Teams!$A$2:$A$49,0)),"") -> Korea Republic | I3: 38 | J3: =IFERROR(INDEX(Teams!$B$2:$B$49,MATCH($I3,Teams!$A$2:$A$49,0)),"") -> Czechia | K3: 2 | L3: 1 | M3: 31 | N3: =IFERROR(INDEX(Teams!$B$2:$B$49,MATCH($M3,Teams!$A$2:$A$49,0)),"Draw") -> Korea Republic | O3: W | P3: 3 | Q3: 1
A4: 3 | B4: 2026-06-12 | C4: First Stage | D4: Group B | E4: 1 | F4: =IFERROR(INDEX(Stadiums!$B$2:$B$17,MATCH($E4,Stadiums!$A$2:$A$17,0)),"") -> Toronto Stadium | G4: 16 | H4: =IFERROR(INDEX(Teams!$B$2:$B$49,MATCH($G4,Teams!$A$2:$A$49,0)),"") -> Canada | I4: 26 | J4: =IFERROR(INDEX(Teams!$B$2:$B$49,MATCH($I4,Teams!$A$2:$A$49,0)),"") -> Bosnia and Herzegovina | K4: 1 | L4: 1 | N4: =IFERROR(INDEX(Teams!$B$2:$B$49,MATCH($M4,Teams!$A$2:$A$49,0)),"Draw") -> Draw | O4: D | P4: 2 | Q4: 0
A5: 4 | B5: 2026-06-12 | C5: First Stage | D5: Group D | E5: 11 | F5: =IFERROR(INDEX(Stadiums!$B$2:$B$17,MATCH($E5,Stadiums!$A$2:$A$17,0)),"") -> Los Angeles Stadium | G5: 12 | H5: =IFERROR(INDEX(Teams!$B$2:$B$49,MATCH($G5,Teams!$A$2:$A$49,0)),"") -> USA | I5: 32 | J5: =IFERROR(INDEX(Teams!$B$2:$B$49,MATCH($I5,Teams!$A$2:$A$49,0)),"") -> Paraguay | K5: 4 | L5: 1 | M5: 12 | N5: =IFERROR(INDEX(Teams!$B$2:$B$49,MATCH($M5,Teams!$A$2:$A$49,0)),"Draw") -> USA | O5: W | P5: 5 | Q5: 3
A6: 5 | B6: 2026-06-13 | C6: First Stage | D6: Group C | E6: 7 | F6: =IFERROR(INDEX(Stadiums!$B$2:$B$17,MATCH($E6,Stadiums!$A$2:$A$17,0)),"") -> Boston Stadium | G6: 39 | H6: =IFERROR(INDEX(Teams!$B$2:$B$49,MATCH($G6,Teams!$A$2:$A$49,0)),"") -> Haiti | I6: 33 | J6: =IFERROR(INDEX(Teams!$B$2:$B$49,MATCH($I6,Teams!$A$2:$A$49,0)),"") -> Scotland | K6: 0 | L6: 1 | M6: 33 | N6: =IFERROR(INDEX(Teams!$B$2:$B$49,MATCH($M6,Teams!$A$2:$A$49,0)),"Draw") -> Scotland | O6: L | P6: 1 | Q6: 1
A7: 6 | B7: 2026-06-13 | C7: First Stage | D7: Group D | E7: 2 | F7: =IFERROR(INDEX(Stadiums!$B$2:$B$17,MATCH($E7,Stadiums!$A$2:$A$17,0)),"") -> BC Place Vancouver | G7: 13 | H7: =IFERROR(INDEX(Teams!$B$2:$B$49,MATCH($G7,Teams!$A$2:$A$49,0)),"") -> Australia | I7: 47 | J7: =IFERROR(INDEX(Teams!$B$2:$B$49,MATCH($I7,Teams!$A$2:$A$49,0)),"") -> Türkiye | K7: 2 | L7: 0 | M7: 13 | N7: =IFERROR(INDEX(Teams!$B$2:$B$49,MATCH($M7,Teams!$A$2:$A$49,0)),"Draw") -> Australia | O7: W | P7: 2 | Q7: 2
A8: 7 | B8: 2026-06-13 | C8: First Stage | D8: Group C | E8: 13 | F8: =IFERROR(INDEX(Stadiums!$B$2:$B$17,MATCH($E8,Stadiums!$A$2:$A$17,0)),"") -> New York New Jersey Stadium | G8: 3 | H8: =IFERROR(INDEX(Teams!$B$2:$B$49,MATCH($G8,Teams!$A$2:$A$49,0)),"") -> Brazil | I8: 21 | J8: =IFERROR(INDEX(Teams!$B$2:$B$49,MATCH($I8,Teams!$A$2:$A$49,0)),"") -> Morocco | K8: 1 | L8: 1 | N8: =IFERROR(INDEX(Teams!$B$2:$B$49,MATCH($M8,Teams!$A$2:$A$49,0)),"Draw") -> Draw | O8: D | P8: 2 | Q8: 0
A9: 8 | B9: 2026-06-13 | C9: First Stage | D9: Group B | E9: 15 | F9: =IFERROR(INDEX(Stadiums!$B$2:$B$17,MATCH($E9,Stadiums!$A$2:$A$17,0)),"") -> San Francisco Bay Area Stadium | G9: 44 | H9: =IFERROR(INDEX(Teams!$B$2:$B$49,MATCH($G9,Teams!$A$2:$A$49,0)),"") -> Qatar | I9: 11 | J9: =IFERROR(INDEX(Teams!$B$2:$B$49,MATCH($I9,Teams!$A$2:$A$49,0)),"") -> Switzerland | K9: 1 | L9: 1 | N9: =IFERROR(INDEX(Teams!$B$2:$B$49,MATCH($M9,Teams!$A$2:$A$49,0)),"Draw") -> Draw | O9: D | P9: 2 | Q9: 0
A10: 9 | B10: 2026-06-14 | C10: First Stage | D10: Group E | E10: 14 | F10: =IFERROR(INDEX(Stadiums!$B$2:$B$17,MATCH($E10,Stadiums!$A$2:$A$17,0)),"") -> Philadelphia Stadium | G10: 17 | H10: =IFERROR(INDEX(Teams!$B$2:$B$49,MATCH($G10,Teams!$A$2:$A$49,0)),"") -> Côte d'Ivoire | I10: 28 | J10: =IFERROR(INDEX(Teams!$B$2:$B$49,MATCH($I10,Teams!$A$2:$A$49,0)),"") -> Ecuador | K10: 1 | L10: 0 | M10: 17 | N10: =IFERROR(INDEX(Teams!$B$2:$B$49,MATCH($M10,Teams!$A$2:$A$49,0)),"Draw") -> Côte d'Ivoire | O10: W | P10: 1 | Q10: 1
A11: 10 | B11: 2026-06-14 | C11: First Stage | D11: Group E | E11: 9 | F11: =IFERROR(INDEX(Stadiums!$B$2:$B$17,MATCH($E11,Stadiums!$A$2:$A$17,0)),"") -> Houston Stadium | G11: 7 | H11: =IFERROR(INDEX(Teams!$B$2:$B$49,MATCH($G11,Teams!$A$2:$A$49,0)),"") -> Germany | I11: 37 | J11: =IFERROR(INDEX(Teams!$B$2:$B$49,MATCH($I11,Teams!$A$2:$A$49,0)),"") -> Curaçao | K11: 7 | L11: 1 | M11: 7 | N11: =IFERROR(INDEX(Teams!$B$2:$B$49,MATCH($M11,Teams!$A$2:$A$49,0)),"Draw") -> Germany | O11: W | P11: 8 | Q11: 6
A12: 11 | B12: 2026-06-14 | C12: First Stage | D12: Group F | E12: 8 | F12: =IFERROR(INDEX(Stadiums!$B$2:$B$17,MATCH($E12,Stadiums!$A$2:$A$17,0)),"") -> Dallas Stadium | G12: 9 | H12: =IFERROR(INDEX(Teams!$B$2:$B$49,MATCH($G12,Teams!$A$2:$A$49,0)),"") -> Netherlands | I12: 20 | J12: =IFERROR(INDEX(Teams!$B$2:$B$49,MATCH($I12,Teams!$A$2:$A$49,0)),"") -> Japan | K12: 2 | L12: 2 | N12: =IFERROR(INDEX(Teams!$B$2:$B$49,MATCH($M12,Teams!$A$2:$A$49,0)),"Draw") -> Draw | O12: D | P12: 4 | Q12: 0
A13: 12 | B13: 2026-06-14 | C13: First Stage | D13: Group F | E13: 5 | F13: =IFERROR(INDEX(Stadiums!$B$2:$B$17,MATCH($E13,Stadiums!$A$2:$A$17,0)),"") -> Estadio Monterrey | G13: 35 | H13: =IFERROR(INDEX(Teams!$B$2:$B$49,MATCH($G13,Teams!$A$2:$A$49,0)),"") -> Sweden | I13: 46 | J13: =IFERROR(INDEX(Teams!$B$2:$B$49,MATCH($I13,Teams!$A$2:$A$49,0)),"") -> Tunisia | K13: 5 | L13: 1 | M13: 35 | N13: =IFERROR(INDEX(Teams!$B$2:$B$49,MATCH($M13,Teams!$A$2:$A$49,0)),"Draw") -> Sweden | O13: W | P13: 6 | Q13: 4
A14: 13 | B14: 2026-06-15 | C14: First Stage | D14: Group H | E14: 12 | F14: =IFERROR(INDEX(Stadiums!$B$2:$B$17,MATCH($E14,Stadiums!$A$2:$A$17,0)),"") -> Miami Stadium | G14: 45 | H14: =IFERROR(INDEX(Teams!$B$2:$B$49,MATCH($G14,Teams!$A$2:$A$49,0)),"") -> Saudi Arabia | I14: 36 | J14: =IFERROR(INDEX(Teams!$B$2:$B$49,MATCH($I14,Teams!$A$2:$A$49,0)),"") -> Uruguay | K14: 1 | L14: 1 | N14: =IFERROR(INDEX(Teams!$B$2:$B$49,MATCH($M14,Teams!$A$2:$A$49,0)),"Draw") -> Draw | O14: D | P14: 2 | Q14: 0
A15: 14 | B15: 2026-06-15 | C15: First Stage | D15: Group H | E15: 6 | F15: =IFERROR(INDEX(Stadiums!$B$2:$B$17,MATCH($E15,Stadiums!$A$2:$A$17,0)),"") -> Atlanta Stadium | G15: 10 | H15: =IFERROR(INDEX(Teams!$B$2:$B$49,MATCH($G15,Teams!$A$2:$A$49,0)),"") -> Spain | I15: 15 | J15: =IFERROR(INDEX(Teams!$B$2:$B$49,MATCH($I15,Teams!$A$2:$A$49,0)),"") -> Cabo Verde | K15: 0 | L15: 0 | N15: =IFERROR(INDEX(Teams!$B$2:$B$49,MATCH($M15,Teams!$A$2:$A$49,0)),"Draw") -> Draw | O15: D | P15: 0 | Q15: 0
A16: 15 | B16: 2026-06-15 | C16: First Stage | D16: Group G | E16: 11 | F16: =IFERROR(INDEX(Stadiums!$B$2:$B$17,MATCH($E16,Stadiums!$A$2:$A$17,0)),"") -> Los Angeles Stadium | G16: 30 | H16: =IFERROR(INDEX(Teams!$B$2:$B$49,MATCH($G16,Teams!$A$2:$A$49,0)),"") -> IR Iran | I16: 42 | J16: =IFERROR(INDEX(Teams!$B$2:$B$49,MATCH($I16,Teams!$A$2:$A$49,0)),"") -> New Zealand | K16: 2 | L16: 2 | N16: =IFERROR(INDEX(Teams!$B$2:$B$49,MATCH($M16,Teams!$A$2:$A$49,0)),"Draw") -> Draw | O16: D | P16: 4 | Q16: 0
A17: 16 | B17: 2026-06-15 | C17: First Stage | D17: Group G | E17: 16 | F17: =IFERROR(INDEX(Stadiums!$B$2:$B$17,MATCH($E17,Stadiums!$A$2:$A$17,0)),"") -> Seattle Stadium | G17: 2 | H17: =IFERROR(INDEX(Teams!$B$2:$B$49,MATCH($G17,Teams!$A$2:$A$49,0)),"") -> Belgium | I17: 19 | J17: =IFERROR(INDEX(Teams!$B$2:$B$49,MATCH($I17,Teams!$A$2:$A$49,0)),"") -> Egypt | K17: 1 | L17: 1 | N17: =IFERROR(INDEX(Teams!$B$2:$B$49,MATCH($M17,Teams!$A$2:$A$49,0)),"Draw") -> Draw | O17: D | P17: 2 | Q17: 0
A18: 17 | B18: 2026-06-16 | C18: First Stage | D18: Group I | E18: 13 | F18: =IFERROR(INDEX(Stadiums!$B$2:$B$17,MATCH($E18,Stadiums!$A$2:$A$17,0)),"") -> New York New Jersey Stadium | G18: 6 | H18: =IFERROR(INDEX(Teams!$B$2:$B$49,MATCH($G18,Teams!$A$2:$A$49,0)),"") -> France | I18: 34 | J18: =IFERROR(INDEX(Teams!$B$2:$B$49,MATCH($I18,Teams!$A$2:$A$49,0)),"") -> Senegal | K18: 3 | L18: 1 | M18: 6 | N18: =IFERROR(INDEX(Teams!$B$2:$B$49,MATCH($M18,Teams!$A$2:$A$49,0)),"Draw") -> France | O18: W | P18: 4 | Q18: 2
A19: 18 | B19: 2026-06-16 | C19: First Stage | D19: Group I | E19: 7 | F19: =IFERROR(INDEX(Stadiums!$B$2:$B$17,MATCH($E19,Stadiums!$A$2:$A$17,0)),"") -> Boston Stadium | G19: 40 | H19: =IFERROR(INDEX(Teams!$B$2:$B$49,MATCH($G19,Teams!$A$2:$A$49,0)),"") -> Iraq | I19: 22 | J19: =IFERROR(INDEX(Teams!$B$2:$B$49,MATCH($I19,Teams!$A$2:$A$49,0)),"") -> Norway | K19: 1 | L19: 4 | M19: 22 | N19: =IFERROR(INDEX(Teams!$B$2:$B$49,MATCH($M19,Teams!$A$2:$A$49,0)),"Draw") -> Norway | O19: L | P19: 5 | Q19: 3
A20: 19 | B20: 2026-06-16 | C20: First Stage | D20: Group J | E20: 10 | F20: =IFERROR(INDEX(Stadiums!$B$2:$B$17,MATCH($E20,Stadiums!$A$2:$A$17,0)),"") -> Kansas City Stadium | G20: 1 | H20: =IFERROR(INDEX(Teams!$B$2:$B$49,MATCH($G20,Teams!$A$2:$A$49,0)),"") -> Argentina | I20: 25 | J20: =IFERROR(INDEX(Teams!$B$2:$B$49,MATCH($I20,Teams!$A$2:$A$49,0)),"") -> Algeria | K20: 3 | L20: 0 | M20: 1 | N20: =IFERROR(INDEX(Teams!$B$2:$B$49,MATCH($M20,Teams!$A$2:$A$49,0)),"Draw") -> Argentina | O20: W | P20: 3 | Q20: 3
A21: 20 | B21: 2026-06-16 | C21: First Stage | D21: Group J | E21: 15 | F21: =IFERROR(INDEX(Stadiums!$B$2:$B$17,MATCH($E21,Stadiums!$A$2:$A$17,0)),"") -> San Francisco Bay Area Stadium | G21: 14 | H21: =IFERROR(INDEX(Teams!$B$2:$B$49,MATCH($G21,Teams!$A$2:$A$49,0)),"") -> Austria | I21: 41 | J21: =IFERROR(INDEX(Teams!$B$2:$B$49,MATCH($I21,Teams!$A$2:$A$49,0)),"") -> Jordan | K21: 3 | L21: 1 | M21: 14 | N21: =IFERROR(INDEX(Teams!$B$2:$B$49,MATCH($M21,Teams!$A$2:$A$49,0)),"Draw") -> Austria | O21: W | P21: 4 | Q21: 2
